Workbook
Name _: #REF!
Name _?: #REF!
Name _ˆó_ü—Ìˆæ: #REF!
Name ___YA002: '[1]1经营'!$E$8
Name ___YA008: [2]T02!$E$23
Name ___YA009: '[1]1经营'!$E$23
Name ___YA015: '[1]1经营'!$E$32
Name ___YA020: '[1]1经营'!$E$39
Name ___YA024: '[1]1经营'!$E$43
Name ___YA028: [2]T02!$E$49
Name ___YA035: '[1]1经营'!$E$55
Name ___YA045: '[1]1经营'!$E$61
Name ___YC001: [2]T02!$E$45
Name ___YC101: '[1]1经营'!$E$47
Name ___YE208: '[1]1经营'!$E$62
Name ___YE210: '[1]1经营'!$E$63
Name ___YE215: '[1]1经营'!$E$64
Name __IntlFixup: TRUE
Name __IVO1: #REF!
Name __q45: {"'용역비'!$A$4:$C$8"}
Name __SUB1: #REF!
Name __SUB2: #REF!
Name __YA002: '[1]1经营'!$E$8
Name __YA008: [2]T02!$E$23
Name __YA009: '[1]1经营'!$E$23
Name __YA015: '[1]1经营'!$E$32
Name __YA020: '[1]1经营'!$E$39
Name __YA024: '[1]1经营'!$E$43
Name __YA028: [2]T02!$E$49
Name __YA035: '[1]1经营'!$E$55
Name __YA045: '[1]1经营'!$E$61
Name __YC001: [2]T02!$E$45
Name __YC101: '[1]1经营'!$E$47
Name __YE208: '[1]1经营'!$E$62
Name __YE210: '[1]1经营'!$E$63
Name __YE215: '[1]1经营'!$E$64
Name _1: #REF!
Name _1_1._제품별_판매목표_내수: [8]전체!#REF!
Name _1_1¤?á?_Cl: #REF!
Name _1_CASH_FLOW: #REF!
Name _1001: #REF!
Name _101600: #REF!
Name _1027: '[12]0001'!#REF!
Name _10월: #REF!
Name _11월: #REF!
Name _12월: #REF!
Name _156: '[12]0001'!#REF!
Name _15A: [13]금액내역서!$D$3:$D$10
Name _1999_01_29: #REF!
Name _1SFT: #REF!
Name _1월: #REF!
Name _1월계획단가: #REF!
Name _2: #REF!
Name _2±è¸íÈ_SW: #REF!
Name _2171: #N/A
Name _2183: #N/A
Name _2187: #N/A
Name _2SFT: #REF!
Name _2월: #REF!
Name _3: #N/A

Sheet FX
B1: Ex rate Information
K2: 평균환율 | L2: 기말환율 | M2: 평균환율 | N2: 기말환율
B3: Currency | C3: 2017(Q4) | D3: 43100 | E3: 2018(Q4) | F3: 43465 | G3: 2019(Q2) | H3: 43646 | I3: 2019(Q3) | J3: 43738 | K3: 2019(Q4) | L3: 43830 | M3: 2020(Q4) | N3: 44196
B4: KRW | C4: 1 | D4: 1 | E4: 1 | F4: 1 | G4: 1 | H4: 1 | I4: 1 | J4: 1 | K4: 1 | L4: 1 | M4: 1 | N4: 1
B5: USD | C5: 1130.84 | D5: 1071.4 | E5: 1100.3 | F5: 1118.1 | G5: 1145.78 | H5: 1156.8 | I5: 1162.18 | J5: 1201.3 | K5: 1165.65 | L5: 1157.8 | M5: 1182.7 | N5: 1088

Sheet A-1. 별도FS_18
C1: IFRS PKG Version
B2: 별도 정산표 v5.0
D3: 0
D4: 0
B5: 43465 | C5: Local Currency | D5: KRW | J5: Disclosure Level - | K5: IFRS | O5: Account Code | P5: Account | Q5: 43465
B6: Account code | C6: Account Name | D6: SDB Korea | J6: Code | K6: Account (P/D Level)) | Q6: K-IFRS
C7: 자산 | P7: 자산 | S7: 자산 | U7: =O7=R7 -> TRUE | V7: =Q7-T7 -> 0
B8: A1000 | C8: 유동자산 | D8: 20601572410 | N8: =O8=B8 -> TRUE | O8: A1000 | P8: 유동자산 | Q8: 20601572410 | R8: A1000 | S8: 유동자산 | T8: 19598469183 | U8: =O8=R8 -> TRUE | V8: =Q8-T8 -> 1003103227
B9: A1100 | C9: 당좌자산 | D9: 12638713835 | N9: =O9=B9 -> TRUE | O9: A1100 | P9: 당좌자산 | Q9: 12638713835 | R9: A1100 | S9: 당좌자산 | T9: 11635610608 | U9: =O9=R9 -> TRUE | V9: =Q9-T9 -> 1003103227
B10: A1101 | C10: 현금시재 | D10: 0 | J10: A11010 | K10: 현금및현금성자산 | N10: =O10=B10 -> TRUE | O10: A1101 | P10: 현금시재 | Q10: 0 | R10: A1101 | S10: 현금시재 | T10: 0 | U10: =O10=R10 -> TRUE | V10: =Q10-T10 -> 0
B11: A1102 | C11: 보통예금 | D11: 3941765038 | J11: A11010 | K11: 현금및현금성자산 | N11: =O11=B11 -> TRUE | O11: A1102 | P11: 보통예금 | Q11: 3941765038 | R11: A1102 | S11: 보통예금 | T11: 3941765038 | U11: =O11=R11 -> TRUE | V11: =Q11-T11 -> 0
B12: A1103 | C12: 국고보조금-현금및현금성자산 | D12: 0 | J12: A11010 | K12: 현금및현금성자산 | N12: =O12=B12 -> TRUE | O12: A1103 | P12: 국고보조금-현금및현금성자산 | Q12: 0 | R12: A1103 | S12: 국고보조금-현금및현금성자산 | T12: 0 | U12: =O12=R12 -> TRUE | V12: =Q12-T12 -> 0
B13: A1104 | C13: 정기예.적금 | D13: 0 | J13: A11040 | K13: 단기금융상품 | N13: =O13=B13 -> TRUE | O13: A1104 | P13: 정기예.적금 | Q13: 0 | R13: A1104 | S13: 정기예.적금 | T13: 0 | U13: =O13=R13 -> TRUE | V13: =Q13-T13 -> 0
B14: A1105 | C14: 당기손익-공정가치금융자산(유동) | D14: 1003103227 | J14: A11050 | K14: 당기손익-공정가치금융자산(유동) | N14: =O14=B14 -> TRUE | O14: A1105 | P14: 당기손익-공정가치금융자산(유동) | Q14: 1003103227 | R14: A1105 | S14: 당기손익-공정가치금융자산(유동) | T14: 0 | U14: =O14=R14 -> TRUE | V14: =Q14-T14 -> 1003103227
B15: A1106 | C15: 외상매출금 | D15: 7723897995 | J15: A11060 | K15: 매출채권 | N15: =O15=B15 -> TRUE | O15: A1106 | P15: 외상매출금 | Q15: 7723897995 | R15: A1106 | S15: 외상매출금 | T15: 7723897995 | U15: =O15=R15 -> TRUE | V15: =Q15-T15 -> 0
B16: A1106C | C16: 외상매출금/Intercompany | D16: 0 | J16: A11060 | K16: 매출채권 | N16: =O16=B16 -> TRUE | O16: A1106C | P16: 외상매출금/Intercompany | Q16: 0 | R16: A1106C | S16: 외상매출금/Intercompany | T16: 0 | U16: =O16=R16 -> TRUE | V16: =Q16-T16 -> 0
B17: A1106-1 | C17: 현재가치할인차금(유동)-외상매출금 | D17: 0 | J17: A11060 | K17: 매출채권 | N17: =O17=B17 -> TRUE | O17: A1106-1 | P17: 현재가치할인차금(유동)-외상매출금 | Q17: 0 | R17: A1106-1 | S17: 현재가치할인차금(유동)-외상매출금 | T17: 0 | U17: =O17=R17 -> TRUE | V17: =Q17-T17 -> 0
B18: A1107 | C18: 대손충당금-외상매출금 | D18: -713339131 | J18: A11060 | K18: 매출채권 | N18: =O18=B18 -> TRUE | O18: A1107 | P18: 대손충당금-외상매출금 | Q18: -713339131 | R18: A1107 | S18: 대손충당금-외상매출금 | T18: -713339131 | U18: =O18=R18 -> TRUE | V18: =Q18-T18 -> 0
B19: A1107C | C19: 대손충당금-외상매출금/Intercompany | D19: 0 | J19: A11060 | K19: 매출채권 | N19: =O19=B19 -> TRUE | O19: A1107C | P19: 대손충당금-외상매출금/Intercompany | Q19: 0 | R19: A1107C | S19: 대손충당금-외상매출금/Intercompany | T19: 0 | U19: =O19=R19 -> TRUE | V19: =Q19-T19 -> 0
B20: A1109 | C20: 단기대여금 | D20: 0 | J20: A11090 | K20: 기타금융자산 | N20: =O20=B20 -> TRUE | O20: A1109 | P20: 단기대여금 | Q20: 0 | R20: A1109 | S20: 단기대여금 | T20: 0 | U20: =O20=R20 -> TRUE | V20: =Q20-T20 -> 0
B21: A1109-1 | C21: 현재가치할인차금-단기대여금 | D21: 0 | J21: A11090 | K21: 기타금융자산 | N21: =O21=B21 -> TRUE | O21: A1109-1 | P21: 현재가치할인차금-단기대여금 | Q21: 0 | R21: A1109-1 | S21: 현재가치할인차금-단기대여금 | T21: 0 | U21: =O21=R21 -> TRUE | V21: =Q21-T21 -> 0
... B29: A1121 | C29: 반환재고회수권(계약자산) | D29: 0 | J29: A11150 | K29: 기타유동자산 | N29: =O29=B29 -> TRUE | O29: A1121 | P29: 반환재고회수권(계약자산) | Q29: 0 | R29: A1121 | S29: 반환재고회수권(계약자산) | T29: 0 | U29: =O29=R29 -> TRUE | V29: =Q29-T29 -> 0
B30: A1122 | C30: 계약자산 | D30: 0 | N30: =O30=B30 -> TRUE | O30: A1122 | P30: 계약자산 | Q30: 0 | R30: A1122 | S30: 계약자산 | T30: 0 | U30: =O30=R30 -> TRUE | V30: =Q30-T30 -> 0
B31: A1200 | C31: 재고자산 | D31: 7962858575 | J31: 0 | N31: =O31=B31 -> TRUE | O31: A1200 | P31: 재고자산 | Q31: 7962858575 | R31: A1200 | S31: 재고자산 | T31: 7962858575 | U31: =O31=R31 -> TRUE | V31: =Q31-T31 -> 0
B32: A1201 | C32: 상품 | D32: 643428865 | J32: A12001 | K32: 재고자산 | N32: =O32=B32 -> TRUE | O32: A1201 | P32: 상품 | Q32: 643428865 | R32: A1201 | S32: 상품 | T32: 643428865 | U32: =O32=R32 -> TRUE | V32: =Q32-T32 -> 0
B33: A1202 | C33: 제품 | D33: 1601338285 | J33: A12001 | K33: 재고자산 | N33: =O33=B33 -> TRUE | O33: A1202 | P33: 제품 | Q33: 1601338285 | R33: A1202 | S33: 제품 | T33: 1601338285 | U33: =O33=R33 -> TRUE | V33: =Q33-T33 -> 0
B34: A1203 | C34: 제품평가충당금 | D34: 0 | J34: A12001 | K34: 재고자산 | N34: =O34=B34 -> TRUE | O34: A1203 | P34: 제품평가충당금 | Q34: 0 | R34: A1203 | S34: 제품평가충당금 | T34: 0 | U34: =O34=R34 -> TRUE | V34: =Q34-T34 -> 0
B35: A1204 | C35: 원재료 | D35: 3027710531 | J35: A12001 | K35: 재고자산 | N35: =O35=B35 -> TRUE | O35: A1204 | P35: 원재료 | Q35: 3027710531 | R35: A1204 | S35: 원재료 | T35: 3027710531 | U35: =O35=R35 -> TRUE | V35: =Q35-T35 -> 0
B36: A1205 | C36: 원재료평가충당금 | D36: 0 | J36: A12001 | K36: 재고자산 | N36: =O36=B36 -> TRUE | O36: A1205 | P36: 원재료평가충당금 | Q36: 0 | R36: A1205 | S36: 원재료평가충당금 | T36: 0 | U36: =O36=R36 -> TRUE | V36: =Q36-T36 -> 0
B37: A1206 | C37: 부재료 | D37: 877455290 | J37: A12001 | K37: 재고자산 | N37: =O37=B37 -> TRUE | O37: A1206 | P37: 부재료 | Q37: 877455290 | R37: A1206 | S37: 부재료 | T37: 877455290 | U37: =O37=R37 -> TRUE | V37: =Q37-T37 -> 0
B38: A1207 | C38: 재공품 | D38: 1791962192 | J38: A12001 | K38: 재고자산 | N38: =O38=B38 -> TRUE | O38: A1207 | P38: 재공품 | Q38: 1791962192 | R38: A1207 | S38: 재공품 | T38: 1791962192 | U38: =O38=R38 -> TRUE | V38: =Q38-T38 -> 0
B39: A1208 | C39: 재공품평가충당금 | D39: 0 | J39: A12001 | K39: 재고자산 | N39: =O39=B39 -> TRUE | O39: A1208 | P39: 재공품평가충당금 | Q39: 0 | R39: A1208 | S39: 재공품평가충당금 | T39: 0 | U39: =O39=R39 -> TRUE | V39: =Q39-T39 -> 0
B40: A1209 | C40: 반제품 | D40: 0 | J40: A12001 | K40: 재고자산 | N40: =O40=B40 -> TRUE | O40: A1209 | P40: 반제품 | Q40: 0 | R40: A1209 | S40: 반제품 | T40: 0 | U40: =O40=R40 -> TRUE | V40: =Q40-T40 -> 0
B41: A1210 | C41: 반제품평가충당금 | D41: 0 | J41: A12001 | K41: 재고자산 | N41: =O41=B41 -> TRUE | O41: A1210 | P41: 반제품평가충당금 | Q41: 0 | R41: A1210 | S41: 반제품평가충당금 | T41: 0 | U41: =O41=R41 -> TRUE | V41: =Q41-T41 -> 0
B42: A1211 | C42: 미착품 | D42: 20963412 | J42: A12001 | K42: 재고자산 | N42: =O42=B42 -> TRUE | O42: A1211 | P42: 미착품 | Q42: 20963412 | R42: A1211 | S42: 미착품 | T42: 20963412 | U42: =O42=R42 -> TRUE | V42: =Q42-T42 -> 0
N43: =O43=B43 -> TRUE | U43: =O43=R43 -> TRUE | V43: =Q43-T43 -> 0
B44: A2000 | C44: 비유동자산 | D44: 58490546866 | J44: 0 | N44: =O44=B44 -> TRUE | O44: A2000 | P44: 비유동자산 | Q44: 57949675262 | R44: A2000 | S44: 비유동자산 | T44: 59468906735 | U44: =O44=R44 -> TRUE | V44: =Q44-T44 -> -1519231473
B45: A2100 | C45: 투자자산 | D45: 34484040926 | N45: =O45=B45 -> TRUE | O45: A2100 | P45: 투자자산 | Q45: 33941577450 | R45: A2100 | S45: 투자자산 | T45: 35487144153 | U45: =O45=R45 -> TRUE | V45: =Q45-T45 -> -1545566703
B46: A2103 | C46: 장기대여금 | D46: 0 | J46: A21030 | K46: 기타금융자산(비유동) | N46: =O46=B46 -> TRUE | O46: A2103 | P46: 장기대여금 | Q46: 0 | R46: A2103 | S46: 장기대여금 | T46: 0 | U46: =O46=R46 -> TRUE | V46: =Q46-T46 -> 0
B47: A2103-1 | C47: 현재가치할인차금-장기대여금 | D47: 0 | J47: A21030 | K47: 기타금융자산(비유동) | N47: =O47=B47 -> TRUE | O47: A2103-1 | P47: 현재가치할인차금-장기대여금 | Q47: 0 | R47: A2103-1 | S47: 현재가치할인차금-장기대여금 | T47: 0 | U47: =O47=R47 -> TRUE | V47: =Q47-T47 -> 0
...

Sheet A-1. 별도FS_19
C1: IFRS PKG Version | D1: ='A-1. 별도FS_18'!B2 -> 별도 정산표 v5.0 | E1: PKG V1.0
B2: 연결 정산표 v7.0_A-1. 별도FS
D3: 0 | E3: 0
D4: 0 | E4: 0
B5: 43830 | C5: Local Currency | D5: KRW | E5: USD | J5: Disclosure Level - | K5: IFRS
B6: Account code | C6: Account Name | D6: BN Korea | E6: Bionote USA Inc. | J6: Code | K6: Account (P/D Level))
C7: 자산 | M7: 자산
B8: BS | C8: Ⅰ.유동자산 | D8: 23588598166 | E8: 906761 | L8: BS | M8: Ⅰ.유동자산
C9: (1)당좌자산 | D9: 15831735316 | E9: 906761 | M9: (1)당좌자산
B10: A1101 | C10: 현금시재 | D10: 8772043 | E10: 906761 | J10: A11010 | K10: 현금및현금성자산 | L10: A1101 | M10: 현금시재 | N10: =L10=B10 -> TRUE
B11: A1102 | C11: 보통예금 | D11: 5517522912 | E11: 0 | J11: A11010 | K11: 현금및현금성자산 | L11: A1102 | M11: 보통예금 | N11: =L11=B11 -> TRUE
B12: A1103 | C12: 국고보조금-현금및현금성자산 | D12: 0 | E12: 0 | J12: A11010 | K12: 현금및현금성자산 | L12: A1103 | M12: 국고보조금-현금및현금성자산 | N12: =L12=B12 -> TRUE
B13: A1104 | C13: 정기예.적금 | D13: 0 | E13: 0 | J13: A11040 | K13: 단기금융상품 | L13: A1104 | M13: 정기예.적금 | N13: =L13=B13 -> TRUE
B14: A1105 | C14: 당기손익-공정가치금융자산(유동) | D14: 1001420524 | E14: 0 | J14: A11050 | K14: 당기손익-공정가치금융자산(유동) | L14: A1105 | M14: 당기손익-공정가치금융자산(유동) | N14: =L14=B14 -> TRUE
B15: A1106 | C15: 외상매출금 | D15: 9358066120 | E15: 0 | J15: A11060 | K15: 매출채권 | L15: A1106 | M15: 외상매출금 | N15: =L15=B15 -> TRUE
B16: A1106C | C16: 외상매출금/Intercompany | D16: 0 | E16: 0 | J16: A11060 | K16: 매출채권 | L16: A1106C | M16: 외상매출금/Intercompany | N16: =L16=B16 -> TRUE
B17: A1106-1 | C17: 현재가치할인차금(유동)-외상매출금 | D17: 0 | E17: 0 | J17: A11060 | K17: 매출채권 | L17: A1106-1 | M17: 현재가치할인차금(유동)-외상매출금 | N17: =L17=B17 -> TRUE
B18: A1107 | C18: 대손충당금-외상매출금 | D18: -533323483 | E18: 0 | J18: A11060 | K18: 매출채권 | L18: A1107 | M18: 대손충당금-외상매출금 | N18: =L18=B18 -> TRUE
B19: A1107C | C19: 대손충당금-외상매출금/Intercompany | D19: 0 | E19: 0 | J19: A11060 | K19: 매출채권 | L19: A1107C | M19: 대손충당금-외상매출금/Intercompany | N19: =L19=B19 -> TRUE
B20: A1109 | C20: 단기대여금 | D20: 0 | E20: 0 | J20: A11090 | K20: 기타금융자산 | L20: A1109 | M20: 단기대여금 | N20: =L20=B20 -> TRUE
B21: A1109-1 | C21: 현재가치할인차금-단기대여금 | D21: 0 | E21: 0 | J21: A11090 | K21: 기타금융자산 | L21: A1109-1 | M21: 현재가치할인차금-단기대여금 | N21: =L21=B21 -> TRUE
... B28: A1121 | C28: 반환재고회수권(계약자산) | D28: 0 | E28: 0 | J28: A11150 | K28: 기타유동자산 | L28: A1121 | M28: 반환재고회수권(계약자산) | N28: =L28=B28 -> TRUE
C29: (2)재고자산 | D29: 7756862850 | E29: 0 | M29: (2)재고자산 | N29: =L29=B29 -> TRUE
B30: A1201 | C30: 상품 | D30: 545308589 | E30: 0 | J30: A12001 | K30: 재고자산 | L30: A1201 | M30: 상품 | N30: =L30=B30 -> TRUE
B31: A1202 | C31: 제품 | D31: 524830179 | E31: 0 | J31: A12001 | K31: 재고자산 | L31: A1202 | M31: 제품 | N31: =L31=B31 -> TRUE
B32: A1203 | C32: 제품평가충당금 | D32: 0 | E32: 0 | J32: A12001 | K32: 재고자산 | L32: A1203 | M32: 제품평가충당금 | N32: =L32=B32 -> TRUE
B33: A1204 | C33: 원재료 | D33: 3077150977 | E33: 0 | J33: A12001 | K33: 재고자산 | L33: A1204 | M33: 원재료 | N33: =L33=B33 -> TRUE
B34: A1205 | C34: 원재료평가충당금 | D34: 0 | E34: 0 | J34: A12001 | K34: 재고자산 | L34: A1205 | M34: 원재료평가충당금 | N34: =L34=B34 -> TRUE
B35: A1206 | C35: 부재료 | D35: 920887954 | E35: 0 | J35: A12001 | K35: 재고자산 | L35: A1206 | M35: 부재료 | N35: =L35=B35 -> TRUE
B36: A1207 | C36: 재공품 | D36: 2682244471 | E36: 0 | J36: A12001 | K36: 재고자산 | L36: A1207 | M36: 재공품 | N36: =L36=B36 -> TRUE
B37: A1208 | C37: 재공품평가충당금 | D37: 0 | E37: 0 | J37: A12001 | K37: 재고자산 | L37: A1208 | M37: 재공품평가충당금 | N37: =L37=B37 -> TRUE
B38: A1209 | C38: 반제품 | D38: 0 | E38: 0 | J38: A12001 | K38: 재고자산 | L38: A1209 | M38: 반제품 | N38: =L38=B38 -> TRUE
B39: A1210 | C39: 반제품평가충당금 | D39: 0 | E39: 0 | J39: A12001 | K39: 재고자산 | L39: A1210 | M39: 반제품평가충당금 | N39: =L39=B39 -> TRUE
B40: A1211 | C40: 미착품 | D40: 6440680 | E40: 0 | J40: A12001 | K40: 재고자산 | L40: A1211 | M40: 미착품 | N40: =L40=B40 -> TRUE
B41: BS | C41: Ⅱ.비유동자산 | D41: 107600242493 | E41: 7486 | L41: BS | M41: Ⅱ.비유동자산 | N41: =L41=B41 -> TRUE
B42: A2103 | C42: 장기대여금 | D42: 0 | E42: 0 | J42: A21030 | K42: 기타금융자산(비유동) | L42: A2103 | M42: 장기대여금 | N42: =L42=B42 -> TRUE
B43: A2103-1 | C43: 현재가치할인차금-장기대여금 | D43: 0 | E43: 0 | J43: A21030 | K43: 기타금융자산(비유동) | L43: A2103-1 | M43: 현재가치할인차금-장기대여금 | N43: =L43=B43 -> TRUE
B44: A2102 | C44: 당기손익-공정가치금융자산(비유동) | D44: 1059412860 | E44: 0 | J44: A21020 | K44: 당기손익-공정가치금융자산(비유동) | L44: A2102 | M44: 당기손익-공정가치금융자산(비유동) | N44: =L44=B44 -> TRUE
B45: A2104 | C45: 장기매도가능증권 | D45: 0 | E45: 0 | J45: A21040 | K45: 매도가능금융자산 | L45: A2104 | M45: 장기매도가능증권 | N45: =L45=B45 -> TRUE
B46: A2106 | C46: 종속기업투자 | D46: 1179726013 | E46: 0 | J46: A21060 | K46: 종속관계기업투자 | L46: A2106 | M46: 종속기업투자 | N46: =L46=B46 -> TRUE
...

Sheet A-1. 별도FS_20
C1: IFRS PKG Version | D1: 연결 v6.0 | E1: PKG V1.0
D3: =D88-D150 -> 0 | E3: =E88-E150 -> 0 | J3: =J88-J150 -> 0 | L3: =L88-L150 -> 0 | M3: =M88-M150 -> 0 | N3: =N88-N150 -> 0
D4: =D142-D242 -> 0 | E4: =E142-E242 -> 0 | J4: =J143-J242 -> 0 | L4: =L143-L242 -> 0
B5: ='[195]A. 별도FS 환산'!B5 -> 44196 | C5: Local Currency | D5: ='[195]A. 별도FS 환산'!E3 -> KRW | E5: ='[195]A. 별도FS 환산'!F3 -> USD | P5: Disclosure Level - | Q5: IFRS | U5: Account Code | V5: Account
B6: Account code | C6: Account Name | D6: BN Korea | E6: Bionote USA Inc. | P6: Code | Q6: Account (P/D Level))
C7: 자산 | V7: 자산
B8: BS | C8: Ⅰ.유동자산 | D8: 572917913876 | E8: =SUM(E9,E30) -> 1135202 | J8: =SUM(J10:J30) -> 0 | K8: =SUM(K10:K30) -> 0 | L8: =SUM(L10:L30) -> 0 | M8: =SUM(M10:M30) -> 0 | N8: =SUM(N10:N30) -> 0 | U8: A1000 | V8: 유동자산 | W8: =U8=B8 -> FALSE | X8: =V8=C8 -> FALSE
C9: (1)당좌자산 | D9: 519871359963 | E9: =SUM(E10:E29) -> 1091484 | U9: A1100 | V9: 당좌자산 | W9: =U9=B9 -> FALSE | X9: =V9=C9 -> FALSE
B10: A1101 | C10: 현금시재 | D10: 9195143 | E10: 600 | P10: A11010 | Q10: 현금및현금성자산 | U10: A1101 | V10: 현금시재 | W10: =U10=B10 -> TRUE | X10: =V10=C10 -> TRUE
B11: A1102 | C11: 보통예금 | D11: 122537878506 | E11: =501284.39+500000 -> 1001284.4 | P11: A11010 | Q11: 현금및현금성자산 | U11: A1102 | V11: 보통예금 | W11: =U11=B11 -> TRUE | X11: =V11=C11 -> TRUE
B12: A1103 | C12: 국고보조금-현금및현금성자산 | D12: -13293321 | E12: 0 | P12: A11010 | Q12: 현금및현금성자산 | U12: A1103 | V12: 국고보조금-현금및현금성자산 | W12: =U12=B12 -> TRUE | X12: =V12=C12 -> TRUE
B13: A1104 | C13: 정기예.적금 | D13: 40000000000 | E13: 0 | P13: A11040 | Q13: 단기금융상품 | U13: A1104 | V13: 정기예.적금 | W13: =U13=B13 -> TRUE | X13: =V13=C13 -> TRUE
B14: A1105 | C14: 당기손익-공정가치금융자산(유동) | D14: 40530571199 | E14: 0 | P14: A11050 | Q14: 당기손익-공정가치금융자산(유동) | U14: A1105 | V14: 당기손익-공정가치금융자산(유동) | W14: =U14=B14 -> TRUE | X14: =V14=C14 -> TRUE
B15: A1106 | C15: 외상매출금 | D15: 311239364207 | E15: 89599.64 | P15: A11060 | Q15: 매출채권 | U15: A1106 | V15: 외상매출금 | W15: =U15=B15 -> TRUE | X15: =V15=C15 -> TRUE
B16: A1106C | C16: 외상매출금/Intercompany | D16: 0 | E16: 0 | P16: A11060 | Q16: 매출채권 | U16: A1106C | V16: 외상매출금/Intercompany | W16: =U16=B16 -> TRUE | X16: =V16=C16 -> TRUE
B17: A1106-1 | C17: 현재가치할인차금(유동)-외상매출금 | D17: 0 | E17: 0 | P17: A11060 | Q17: 매출채권 | U17: A1106-1 | V17: 현재가치할인차금(유동)-외상매출금 | W17: =U17=B17 -> TRUE | X17: =V17=C17 -> TRUE
B18: A1107 | C18: 대손충당금-외상매출금 | D18: -619075951 | E18: 0 | P18: A11060 | Q18: 매출채권 | U18: A1107 | V18: 대손충당금-외상매출금 | W18: =U18=B18 -> TRUE | X18: =V18=C18 -> TRUE
B19: A1107C | C19: 대손충당금-외상매출금/Intercompany | D19: 0 | E19: 0 | P19: A11060 | Q19: 매출채권 | U19: A1107C | V19: 대손충당금-외상매출금/Intercompany | W19: =U19=B19 -> TRUE | X19: =V19=C19 -> TRUE
B20: A1109 | C20: 단기대여금 | D20: 0 | E20: 0 | P20: A11090 | Q20: 기타금융자산 | U20: A1109 | V20: 단기대여금 | W20: =U20=B20 -> TRUE | X20: =V20=C20 -> TRUE
B21: A1109-1 | C21: 현재가치할인차금-단기대여금 | D21: 0 | E21: 0 | P21: A11090 | Q21: 기타금융자산 | U21: A1109-1 | V21: 현재가치할인차금-단기대여금 | W21: =U21=B21 -> TRUE | X21: =V21=C21 -> TRUE
B22: A1111 | C22: 미수수익 | D22: 0 | E22: 0 | P22: A11090 | Q22: 기타금융자산 | U22: A1111 | V22: 미수수익 | W22: =U22=B22 -> TRUE | X22: =V22=C22 -> TRUE
B23: A1112 | C23: 미수금 | D23: 86832198 | E23: 0 | P23: A11090 | Q23: 기타금융자산 | U23: A1112 | V23: 미수금 | W23: =U23=B23 -> TRUE | X23: =V23=C23 -> TRUE
... B25: A1116 | C25: 선급비용 | D25: 20109358 | E25: 0 | P25: A11150 | Q25: 기타유동자산 | U25: A1116 | V25: 선급비용 | W25: =U25=B25 -> TRUE | X25: =V25=C25 -> TRUE
B26: A1117 | C26: 부가세대급금 | D26: 0 | E26: 0 | P26: A11150 | Q26: 기타유동자산 | U26: A1117 | V26: 부가세대급금
B27: A1119 | C27: 당기법인세자산 | D27: 0 | E27: 0 | P27: A11190 | Q27: 당기법인세자산 | U27: A1119 | V27: 당기법인세자산 | W27: =U27=B27 -> TRUE | X27: =V27=C27 -> TRUE
B28: A1118 | C28: 유동성이연법인세자산 | D28: 0 | E28: 0 | P28: A11180 | Q28: 이연법인세자산 | U28: A1118 | V28: 유동성이연법인세자산 | W28: =U28=B28 -> TRUE | X28: =V28=C28 -> TRUE
B29: A1121 | C29: 반환재고회수권(계약자산) | D29: 0 | E29: 0 | P29: A11150 | Q29: 기타유동자산 | U29: A1121 | V29: 반환재고회수권(계약자산) | W29: =U29=B29 -> TRUE | X29: =V29=C29 -> TRUE
C30: (2)재고자산 | D30: 53046553913 | E30: 43718 | U30: A1122 | V30: 계약자산 | W30: =U30=B30 -> FALSE | X30: =V30=C30 -> FALSE
B31: A1201 | C31: 상품 | D31: 1024597346 | E31: 43718 | P31: A12001 | Q31: 재고자산 | U31: A1200 | V31: 재고자산 | W31: =U31=B31 -> FALSE | X31: =V31=C31 -> FALSE
B32: A1202 | C32: 제품 | D32: 9749294700 | E32: 0 | P32: A12001 | Q32: 재고자산 | U32: A1201 | V32: 상품 | W32: =U32=B32 -> FALSE | X32: =V32=C32 -> FALSE
B33: A1203 | C33: 제품평가충당금 | D33: -692503942 | E33: 0 | P33: A12001 | Q33: 재고자산 | U33: A1202 | V33: 제품 | W33: =U33=B33 -> FALSE | X33: =V33=C33 -> FALSE
B34: A1204 | C34: 원재료 | D34: 17942503420 | E34: 0 | P34: A12001 | Q34: 재고자산 | U34: A1203 | V34: 제품평가충당금 | W34: =U34=B34 -> FALSE | X34: =V34=C34 -> FALSE
B35: A1205 | C35: 원재료평가충당금 | D35: -840869466 | E35: 0 | P35: A12001 | Q35: 재고자산 | U35: A1204 | V35: 원재료 | W35: =U35=B35 -> FALSE | X35: =V35=C35 -> FALSE
B36: A1206 | C36: 부재료 | D36: 8982567553 | E36: 0 | P36: A12001 | Q36: 재고자산 | U36: A1205 | V36: 원재료평가충당금 | W36: =U36=B36 -> FALSE | X36: =V36=C36 -> FALSE
B37: A1207 | C37: 재공품 | D37: 17547814739 | E37: 0 | P37: A12001 | Q37: 재고자산 | U37: A1206 | V37: 부재료 | W37: =U37=B37 -> FALSE | X37: =V37=C37 -> FALSE
B38: A1208 | C38: 재공품평가충당금 | D38: -1033566288 | E38: 0 | P38: A12001 | Q38: 재고자산 | U38: A1207 | V38: 재공품 | W38: =U38=B38 -> FALSE | X38: =V38=C38 -> FALSE
B39: A1209 | C39: 반제품 | D39: 0 | E39: 0 | P39: A12001 | Q39: 재고자산 | U39: A1208 | V39: 재공품평가충당금 | W39: =U39=B39 -> FALSE | X39: =V39=C39 -> FALSE
B40: A1210 | C40: 반제품평가충당금 | D40: 0 | E40: 0 | P40: A12001 | Q40: 재고자산 | U40: A1209 | V40: 반제품 | W40: =U40=B40 -> FALSE | X40: =V40=C40 -> FALSE
B41: A1211 | C41: 미착품 | D41: 366715851 | E41: 0 | P41: A12001 | Q41: 재고자산 | U41: A1210 | V41: 반제품평가충당금 | W41: =U41=B41 -> FALSE | X41: =V41=C41 -> FALSE
B42: BS | C42: Ⅱ.비유동자산 | D42: 1.3993539e+11 | E42: 11047.35 | J42: =SUM(J43:J57,J78,J87) -> 0 | L42: =SUM(L43:L57,L78,L87) -> 0 | M42: =SUM(M43:M57,M78,M87) -> 0 | N42: =SUM(N43:N57,N78,N87) -> 0 | U42: A1211 | V42: 미착품 | W42: =U42=B42 -> FALSE | X42: =V42=C42 -> FALSE
...

Sheet C.연결조정 정산표_20
K1: 0
B2: IFRS Consolidation Worksheet | E2: Date : | F2: 44196
E3: 2020 연결 정산표 V6.0
B4: Account code | C4: Account code | D4: Account Name | E4: 연결정산표 | F4: 단순합산 | G4: 연결조정분개 | I4: 조정금액 순효과 | J4: 연결정산표 | K4: 전기말 대비 변동 | L4: 비고
B5: High Level | C5: Low Level | D5: Account Name | E5: 43830 | F5: 44196 | G5: 차변 | H5: 대변 | I5: 조정금액 순효과 | J5: 44196
B6: 0 | C6: 0 | D6: 자산 | O6: 0 | P6: 자산 | Q6: =O6=C6 -> TRUE
B7: 0 | C7: BS | D7: Ⅰ.유동자산 | E7: 24638446052 | F7: 573609013684 | J7: 573427894914 | K7: 548789448862 | O7: BS | P7: Ⅰ.유동자산 | Q7: =O7=C7 -> TRUE
B8: A11010 | C8: A1101 | D8: 현금시재 | E8: 1058619929 | F8: 9847943 | G8: 0 | H8: 0 | I8: 0 | J8: 9847943 | K8: -1048771986 | M8: 현금및현금성자산 | O8: A1101 | P8: 현금시재 | Q8: =O8=C8 -> TRUE
B9: A11010 | C9: A1102 | D9: 보통예금 | E9: 5517522912 | F9: 123083275922 | G9: 0 | H9: 0 | I9: 0 | J9: 123083275922 | K9: 117565753010 | M9: 현금및현금성자산 | O9: A1102 | P9: 보통예금 | Q9: =O9=C9 -> TRUE
B10: A11010 | C10: A1103 | D10: 국고보조금-현금및현금성자산 | E10: 0 | F10: -13293321 | G10: 0 | H10: 0 | I10: 0 | J10: -13293321 | K10: -13293321 | M10: 현금및현금성자산 | O10: A1103 | P10: 국고보조금-현금및현금성자산 | Q10: =O10=C10 -> TRUE
B11: A11040 | C11: A1104 | D11: 정기예.적금 | E11: 0 | F11: 40000000000 | G11: 0 | H11: 0 | I11: 0 | J11: 40000000000 | K11: 40000000000 | M11: 단기금융상품 | O11: A1104 | P11: 정기예.적금 | Q11: =O11=C11 -> TRUE
B12: A11050 | C12: A1105 | D12: 당기손익-공정가치금융자산(유동) | E12: 1001420524 | F12: 40530571199 | G12: 0 | H12: 0 | I12: 0 | J12: 40530571199 | K12: 39529150675 | M12: 당기손익-공정가치금융자산(유동) | O12: A1105 | P12: 당기손익-공정가치금융자산(유동) | Q12: =O12=C12 -> TRUE
B13: A11060 | C13: A1106 | D13: 외상매출금 | E13: 9358066120 | F13: 311336848615 | G13: 0 | H13: 140479840 | I13: -140479840 | J13: 311196368775 | K13: 301838302655 | M13: 매출채권 | O13: A1106 | P13: 외상매출금 | Q13: =O13=C13 -> TRUE
B14: A11060 | C14: A1106C | D14: 외상매출금/Intercompany | E14: 0 | F14: 0 | G14: 0 | H14: 0 | I14: 0 | J14: 0 | K14: 0 | M14: 매출채권 | O14: A1106C | P14: 외상매출금/Intercompany | Q14: =O14=C14 -> TRUE
B15: A11060 | C15: A1106-1 | D15: 현재가치할인차금(유동)-외상매출금 | E15: 0 | F15: 0 | G15: 0 | H15: 0 | I15: 0 | J15: 0 | K15: 0 | M15: 매출채권 | O15: A1106-1 | P15: 현재가치할인차금(유동)-외상매출금 | Q15: =O15=C15 -> TRUE
B16: A11060 | C16: A1107 | D16: 대손충당금-외상매출금 | E16: -533323483 | F16: -619075951 | G16: 0 | H16: 0 | I16: 0 | J16: -619075951 | K16: -85752468 | M16: 매출채권 | O16: A1107 | P16: 대손충당금-외상매출금 | Q16: =O16=C16 -> TRUE
B17: A11060 | C17: A1107C | D17: 대손충당금-외상매출금/Intercompany | E17: 0 | F17: 0 | G17: 0 | H17: 0 | I17: 0 | J17: 0 | K17: 0 | M17: 매출채권 | O17: A1107C | P17: 대손충당금-외상매출금/Intercompany | Q17: =O17=C17 -> TRUE
B18: A11090 | C18: A1109 | D18: 단기대여금 | E18: 0 | F18: 0 | G18: 0 | H18: 0 | I18: 0 | J18: 0 | K18: 0 | M18: 기타금융자산 | O18: A1109 | P18: 단기대여금 | Q18: =O18=C18 -> TRUE
B19: A11090 | C19: A1109-1 | D19: 현재가치할인차금-단기대여금 | E19: 0 | F19: 0 | G19: 0 | H19: 0 | I19: 0 | J19: 0 | K19: 0 | M19: 기타금융자산 | O19: A1109-1 | P19: 현재가치할인차금-단기대여금 | Q19: =O19=C19 -> TRUE
... B27: A11150 | C27: A1121 | D27: 반환재고회수권(계약자산) | E27: 0 | F27: 0 | G27: 0 | H27: 0 | I27: 0 | J27: 0 | K27: 0 | M27: 기타유동자산 | O27: A1121 | P27: 반환재고회수권(계약자산) | Q27: =O27=C27 -> TRUE
B28: 0 | C28: 0 | D28: 재고자산 | E28: 7756862850 | F28: 53094119097 | J28: 53053480167 | K28: 45296617317 | O28: 0 | P28: 재고자산 | Q28: =O28=C28 -> TRUE
B29: A12001 | C29: A1201 | D29: 상품 | E29: 545308589 | F29: 1072162530 | G29: 0 | H29: 40638930 | I29: -40638930 | J29: 1031523600 | K29: 486215011 | M29: 재고자산 | O29: A1201 | P29: 상품 | Q29: =O29=C29 -> TRUE
B30: A12001 | C30: A1202 | D30: 제품 | E30: 524830179 | F30: 9749294700 | G30: 0 | H30: 0 | I30: 0 | J30: 9749294700 | K30: 9224464521 | M30: 재고자산 | O30: A1202 | P30: 제품 | Q30: =O30=C30 -> TRUE
B31: A12001 | C31: A1203 | D31: 제품평가충당금 | E31: 0 | F31: -692503942 | G31: 0 | H31: 0 | I31: 0 | J31: -692503942 | K31: -692503942 | M31: 재고자산 | O31: A1203 | P31: 제품평가충당금 | Q31: =O31=C31 -> TRUE
B32: A12001 | C32: A1204 | D32: 원재료 | E32: 3077150977 | F32: 17942503420 | G32: 0 | H32: 0 | I32: 0 | J32: 17942503420 | K32: 14865352443 | M32: 재고자산 | O32: A1204 | P32: 원재료 | Q32: =O32=C32 -> TRUE
B33: A12001 | C33: A1205 | D33: 원재료평가충당금 | E33: 0 | F33: -840869466 | G33: 0 | H33: 0 | I33: 0 | J33: -840869466 | K33: -840869466 | M33: 재고자산 | O33: A1205 | P33: 원재료평가충당금 | Q33: =O33=C33 -> TRUE
B34: A12001 | C34: A1206 | D34: 부재료 | E34: 920887954 | F34: 8982567553 | G34: 0 | H34: 0 | I34: 0 | J34: 8982567553 | K34: 8061679599 | M34: 재고자산 | O34: A1206 | P34: 부재료 | Q34: =O34=C34 -> TRUE
B35: A12001 | C35: A1207 | D35: 재공품 | E35: 2682244471 | F35: 17547814739 | G35: 0 | H35: 0 | I35: 0 | J35: 17547814739 | K35: 14865570268 | M35: 재고자산 | O35: A1207 | P35: 재공품 | Q35: =O35=C35 -> TRUE
B36: A12001 | C36: A1208 | D36: 재공품평가충당금 | E36: 0 | F36: -1033566288 | G36: 0 | H36: 0 | I36: 0 | J36: -1033566288 | K36: -1033566288 | M36: 재고자산 | O36: A1208 | P36: 재공품평가충당금 | Q36: =O36=C36 -> TRUE
B37: A12001 | C37: A1209 | D37: 반제품 | E37: 0 | F37: 0 | G37: 0 | H37: 0 | I37: 0 | J37: 0 | K37: 0 | M37: 재고자산 | O37: A1209 | P37: 반제품 | Q37: =O37=C37 -> TRUE
B38: A12001 | C38: A1210 | D38: 반제품평가충당금 | E38: 0 | F38: 0 | G38: 0 | H38: 0 | I38: 0 | J38: 0 | K38: 0 | M38: 재고자산 | O38: A1210 | P38: 반제품평가충당금 | Q38: =O38=C38 -> TRUE
B39: A12001 | C39: A1211 | D39: 미착품 | E39: 6440680 | F39: 366715851 | G39: 0 | H39: 0 | I39: 0 | J39: 366715851 | K39: 360275171 | M39: 재고자산 | O39: A1211 | P39: 미착품 | Q39: =O39=C39 -> TRUE
B40: 0 | C40: BS | D40: Ⅱ.비유동자산 | E40: 106192914518 | F40: 139947405170 | J40: 280012168867 | K40: 173819254349 | O40: BS | P40: Ⅱ.비유동자산 | Q40: =O40=C40 -> TRUE
B41: A21030 | C41: A2103 | D41: 장기대여금 | E41: 0 | F41: 0 | G41: 0 | H41: 0 | I41: 0 | J41: 0 | K41: 0 | M41: 기타금융자산(비유동) | O41: A2103 | P41: 장기대여금 | Q41: =O41=C41 -> TRUE
B42: A21030 | C42: A2103-1 | D42: 현재가치할인차금-장기대여금 | E42: 0 | F42: 0 | G42: 0 | H42: 0 | I42: 0 | J42: 0 | K42: 0 | M42: 기타금융자산(비유동) | O42: A2103-1 | P42: 현재가치할인차금-장기대여금 | Q42: =O42=C42 -> TRUE
B43: A21020 | C43: A2102 | D43: 당기손익-공정가치금융자산(비유동) | E43: 1059412860 | F43: 5047622400 | G43: 0 | H43: 0 | I43: 0 | J43: 5047622400 | K43: 3988209540 | M43: 당기손익-공정가치금융자산(비유동) | O43: A2102 | P43: 당기손익-공정가치금융자산(비유동) | Q43: =O43=C43 -> TRUE
B44: A21040 | C44: A2104 | D44: 장기매도가능증권 | E44: 0 | F44: 0 | G44: 0 | H44: 0 | I44: 0 | J44: 0 | K44: 0 | M44: 매도가능금융자산 | O44: A2104 | P44: 장기매도가능증권 | Q44: =O44=C44 -> TRUE
B45: A21060 | C45: A2106 | D45: 종속기업투자 | E45: 0 | F45: 1725826013 | G45: 0 | H45: 1725826013 | I45: -1725826013 | J45: 0 | K45: 0 | M45: 종속관계기업투자 | O45: A2106 | P45: 종속기업투자 | Q45: =O45=C45 -> TRUE
B46: A21060 | C46: A2107 | D46: 관계기업투자 | E46: 81209493461 | F46: 82863041989 | G46: 142092671599 | H46: 302081889 | I46: 141790589710 | J46: 224653631699 | K46: 143444138238 | M46: 종속관계기업투자 | O46: A2107 | P46: 관계기업투자 | Q46: =O46=C46 -> TRUE
B47: A21030 | C47: A2402 | D47: 임차보증금 | E47: 0 | F47: 359044000 | G47: 0 | H47: 0 | I47: 0 | J47: 359044000 | K47: 359044000 | M47: 기타금융자산(비유동) | O47: A2402 | P47: 임차보증금 | Q47: =O47=C47 -> TRUE
...

Sheet 공시CF
K2: 010-9929-5133
C3: 과 목 | D3: 2020 4Q | E3: 2020 4Q | F3: 2020 4Q
D4: 단순합산 CF | E4: 연결조정반영 | F4: 조정후 CF
C5: Ⅰ. 영업활동으로 인한 현금흐름 | D5: =SUM(D6,D48:D51) -> 2.399263e+11 | E5: =SUM(E6,E48:E50) -> 0 | F5: =SUM(F6,F48:F51) -> 239926298207
C6: 1. 영업에서 창출된 현금 | D6: =SUM(D7:D8,D30) -> 2.4104748e+11 | E6: =SUM(E7:E8,E30) -> 0 | F6: =SUM(F7:F8,F30) -> 241047481812
C7: (1) 당기순이익 | D7: =CFwp_Aggregated!I150 -> 4.131142e+11 | E7: =-E18-E16-E33 -> 115114641677 | F7: ='C.연결조정 정산표_20'!J238 -> 528228844808 | G7: =SUM(D7:E7)-F7 -> 0.025024414
C8: (2) 수익비용의 조정 | D8: =SUM(D9:D29) -> 148403986848 | E8: =SUM(E9:E29) -> -115155280607 | F8: =SUM(F9:F29) -> 33248706241 | G8: =CFwp_Aggregated!D161-D8 -> -0.025024414
C9: 외화환산이익 | D9: =-SUMIF(CFwp_Aggregated!$H:$H,공시CF!C9,CFwp_Aggregated!I:I) -> -18175186 | F9: =SUM(D9:E9) -> -18175186 | I9: ='C.연결조정 정산표_20'!J209 -> 18175186 | J9: =SUM(F9:I9) -> 0
C10: 외화환산손실 | D10: =SUMIF(CFwp_Aggregated!$H:$H,공시CF!C10,CFwp_Aggregated!I:I) -> 3635900701 | F10: =SUM(D10:E10) -> 3635900701 | I10: ='C.연결조정 정산표_20'!J218 -> 3635900701 | J10: =SUM(F10:H10)-I10 -> 0 | K10: =I10-I9 -> 3617725515 | L10: =SUM(F9:F10) -> 3617725515 | M10: =K10-L10 -> 0
C11: 금융자산평가이익 | D11: =-ROUND(SUMIF(CFwp_Aggregated!$H:$H,공시CF!C11,CFwp_Aggregated!I:I),) -> -536952215 | F11: =SUM(D11:E11) -> -536952215 | I11: ='C.연결조정 정산표_20'!J227 -> 536952215 | J11: =SUM(F11:I11) -> 0
C12: 금융자산처분이익 | D12: =-SUMIF(CFwp_Aggregated!$H:$H,공시CF!C12,CFwp_Aggregated!I:I) -> -7424862 | F12: =SUM(D12:E12) -> -7424862 | I12: ='C.연결조정 정산표_20'!J228 -> 7424862 | J12: =SUM(F12:I12) -> 0
C13: 대손상각비 | D13: =SUMIF(CFwp_Aggregated!$H:$H,공시CF!C13,CFwp_Aggregated!I:I) -> 470162695 | F13: =SUM(D13:E13) -> 470162695 | I13: ='C.연결조정 정산표_20'!J197 -> 470162695 | J13: =SUM(F13:H13)-I13 -> 0
C14: 재고자산평가손실 | D14: =ROUND(SUMIF(CFwp_Aggregated!$H:$H,공시CF!C14,CFwp_Aggregated!I:I),) -> 2840492158 | F14: =SUM(D14:E14) -> 2840492158
C15: 이자수익(금융) | D15: =-SUMIF(CFwp_Aggregated!$H:$H,공시CF!C15,CFwp_Aggregated!I:I) -> -37557679 | F15: =SUM(D15:E15) -> -37557679 | I15: ='C.연결조정 정산표_20'!J225 -> 37557679 | J15: =SUM(F15:I15) -> 0
C16: 법인세비용 | D16: =SUMIF(CFwp_Aggregated!$H:$H,공시CF!C16,CFwp_Aggregated!I:I) -> 139553435926 | E16: ='B.연결조정분개 요약표'!F90 -> 27415427309 | F16: =SUM(D16:E16) -> 166968863235 | I16: ='C.연결조정 정산표_20'!J237 -> 166968863235 | J16: =SUM(F16:H16)-I16 -> 0
C17: 금융자산평가손실 | D17: =SUMIF(CFwp_Aggregated!$H:$H,공시CF!C17,CFwp_Aggregated!I:I) -> 0 | F17: =SUM(D17:E17) -> 0 | I17: ='C.연결조정 정산표_20'!J232 -> 0 | J17: =SUM(F17:H17)-I17 -> 0
C18: 종속기업의당기손익에대한지분 | D18: =SUMIF(CFwp_Aggregated!$H:$H,공시CF!C18,CFwp_Aggregated!I:I) -> 0 | E18: =-'B.연결조정분개 요약표'!G50-'B.연결조정분개 요약표'!G71 -> -142570707916 | F18: =SUM(D18:E18) -> -142570707916 | I18: ='C.연결조정 정산표_20'!J234 -> 142570707916 | J18: =SUM(F18:I18) -> 0
C19: 투자자산처분이익 | D19: =-SUMIF(CFwp_Aggregated!$H:$H,공시CF!C19,CFwp_Aggregated!I:I) -> 0 | F19: =SUM(D19:E19) -> 0 | I19: ='C.연결조정 정산표_20'!J211 -> 0 | J19: =SUM(F19:I19) -> 0
C20: 감가상각비 | D20: =SUMIF(CFwp_Aggregated!$H:$H,공시CF!C20,CFwp_Aggregated!I:I) -> 1808962764 | F20: =SUM(D20:E20) -> 1808962764 | I20: ='C.연결조정 정산표_20'!J180 -> 214947955 | J20: =SUM(F20:H20)-I20 -> 1594014809 | K20: / 제조원가 및 경상연구개발비 배부비용
C21: 유형자산처분이익 | D21: =-SUMIF(CFwp_Aggregated!$H:$H,공시CF!C21,CFwp_Aggregated!I:I) -> -866446 | F21: =SUM(D21:E21) -> -866446 | I21: ='C.연결조정 정산표_20'!J210 -> 866446 | J21: =SUM(F21:I21) -> 0
C22: 유형자산처분손실 | D22: =SUMIF(CFwp_Aggregated!$H:$H,공시CF!C22,CFwp_Aggregated!I:I) -> 12310639 | F22: =SUM(D22:E22) -> 12310639 | I22: ='C.연결조정 정산표_20'!J222 -> 12310639 | J22: =SUM(F22:H22)-I22 -> 0
C23: 무형자산상각비 | D23: =SUMIF(CFwp_Aggregated!$H:$H,공시CF!C23,CFwp_Aggregated!I:I) -> 78391153 | F23: =SUM(D23:E23) -> 78391153 | I23: ='C.연결조정 정산표_20'!J200 -> 78391153 | J23: =SUM(F23:H23)-I23 -> 0
C24: 이자비용(금융) | D24: =SUMIF(CFwp_Aggregated!$H:$H,공시CF!C24,CFwp_Aggregated!I:I) -> 165715444 | F24: =SUM(D24:E24) -> 165715444 | I24: ='C.연결조정 정산표_20'!J230 -> 172627980 | J24: =SUM(F24:H24)-I24 -> -6912536
C25: 이자비용(리스) | D25: =SUMIF(CFwp_Aggregated!$H:$H,공시CF!C25,CFwp_Aggregated!I:I) -> 6912536 | F25: =SUM(D25:E25) -> 6912536 | J25: =SUM(F25:H25)-I25 -> 6912536
C26: 연차충당부채전입 | D26: =SUMIF(CFwp_Aggregated!$H:$H,공시CF!C26,CFwp_Aggregated!I:I) -> 68990899 | F26: =SUM(D26:E26) -> 68990899
C27: 주식보상비용 | D27: =SUMIF(CFwp_Aggregated!$H:$H,공시CF!C27,CFwp_Aggregated!I:I) -> 348063905 | F27: =SUM(D27:E27) -> 348063905 | I27: ='C.연결조정 정산표_20'!J202 -> 348063905 | J27: =SUM(F27:H27)-I27 -> 0
C28: 장기종업원급여 | D28: =SUMIF(CFwp_Aggregated!$H:$H,공시CF!C28,CFwp_Aggregated!I:I) -> 15624416 | F28: =SUM(D28:E28) -> 15624416
D29: =SUMIF(CFwp_Aggregated!$H:$H,공시CF!C29,CFwp_Aggregated!I:I) -> 0 | F29: =SUM(D29:E29) -> 0
C30: (3) 자산부채의 변동 | D30: =SUM(D31:D47) -> -320470708167 | E30: =SUM(E31:E47) -> 40638930 | F30: =SUM(F31:F47) -> -320430069237 | G30: =D30-CFwp_Aggregated!D162 -> 0 | J30: 내부거래 상계 | L30: =SUM(L32:L36)-SUM(L37:L43) -> 280959680 | M30: =SUM(M32:M36)-SUM(M37:M43) -> 0 | N30: =SUM(N32:N36)-SUM(N37:N43) -> 280959680
A31: =CFwp_Aggregated!B16 -> A1106 | B31: =CFwp_Aggregated!B19 -> A1106-1 | C31: 매출채권 | D31: =SUMIF(CFwp_Aggregated!$B:$B,공시CF!B31,CFwp_Aggregated!$L:$L)+SUMIF(CFwp_Aggregated!$B:$B,공시CF!A31,CFwp_Aggregated!$L:$L) -> -305620951415 | E31: =L32 -> 140479840 | F31: =SUM(D31:E31) -> -305480471575 | L31: 2020 | M31: 2019
A32: =CFwp_Aggregated!B92 -> A2406 | C32: 비유동매출채권 | D32: =SUMIF(CFwp_Aggregated!$B:$B,공시CF!B32,CFwp_Aggregated!$L:$L)+SUMIF(CFwp_Aggregated!$B:$B,공시CF!A32,CFwp_Aggregated!$L:$L) -> 0 | F32: =SUM(D32:E32) -> 0 | K32: 매출채권/Intercompany | L32: ='B.연결조정분개 요약표'!G19 -> 140479840 | N32: =L32-M32 -> 140479840 | O32: 자산의 감소 -> 현금의 증가
A33: A1200 | C33: 재고자산 | D33: =SUMIF(CFwp_Aggregated!$B:$B,공시CF!B33,CFwp_Aggregated!$L:$L)+SUMIF(CFwp_Aggregated!$B:$B,공시CF!A33,CFwp_Aggregated!$L:$L) -> -48181888500 | E33: ='B.연결조정분개 요약표'!G28 -> 40638930 | F33: =SUM(D33:E33) -> -48141249570 | K33: 미수금 | N33: =L33-M33 -> 0
A34: =CFwp_Aggregated!B25 -> A1112 | C34: 미수금 | D34: =SUMIF(CFwp_Aggregated!$B:$B,공시CF!B34,CFwp_Aggregated!$L:$L)+SUMIF(CFwp_Aggregated!$B:$B,공시CF!A34,CFwp_Aggregated!$L:$L) -> 57479025 | F34: =SUM(D34:E34) -> 57479025 | K34: 비유동매출채권/Intercompany | N34: =L34-M34 -> 0
A35: =CFwp_Aggregated!B26 -> A1115 | C35: 선급금 | D35: =SUMIF(CFwp_Aggregated!$B:$B,공시CF!B35,CFwp_Aggregated!$L:$L)+SUMIF(CFwp_Aggregated!$B:$B,공시CF!A35,CFwp_Aggregated!$L:$L) -> -6233813988 | F35: =SUM(D35:E35) -> -6233813988 | K35: 미수수익 | N35: =L35-M35 -> 0
A36: =CFwp_Aggregated!B27 -> A1116 | C36: 선급비용 | D36: =SUMIF(CFwp_Aggregated!$B:$B,공시CF!B36,CFwp_Aggregated!$L:$L)+SUMIF(CFwp_Aggregated!$B:$B,공시CF!A36,CFwp_Aggregated!$L:$L) -> 6719678 | F36: =SUM(D36:E36) -> 6719678 | K36: 단기대여금 | N36: =L36-M36 -> 0
A37: A1117 | C37: 부가세대급금 | D37: =SUMIF(CFwp_Aggregated!$B:$B,공시CF!B37,CFwp_Aggregated!$L:$L)+SUMIF(CFwp_Aggregated!$B:$B,공시CF!A37,CFwp_Aggregated!$L:$L) -> 0 | F37: =SUM(D37:E37) -> 0 | K37: 매입채무/Intercompany | N37: =L37-M37 -> 0 | O37: 부채의 감소 -> 현금의 감소
A38: A1122 | C38: 계약자산 | D38: =SUMIF(CFwp_Aggregated!$B:$B,공시CF!B38,CFwp_Aggregated!$L:$L)+SUMIF(CFwp_Aggregated!$B:$B,공시CF!A38,CFwp_Aggregated!$L:$L) -> 0 | F38: =SUM(D38:E38) -> 0 | K38: 미지급금/Intercompany | L38: =-L32 -> -140479840 | N38: =L38-M38 -> -140479840
A39: =CFwp_Aggregated!B102 -> L1001 | C39: 매입채무 | D39: =SUMIF(CFwp_Aggregated!$B:$B,공시CF!B39,CFwp_Aggregated!$L:$L)+SUMIF(CFwp_Aggregated!$B:$B,공시CF!A39,CFwp_Aggregated!$L:$L) -> 27512964306 | F39: =SUM(D39:E39) -> 27512964306 | K39: 미지급비용 | N39: =L39-M39 -> 0
A40: =CFwp_Aggregated!B112 -> L1017 | C40: 계약부채 | D40: =SUMIF(CFwp_Aggregated!$B:$B,공시CF!B40,CFwp_Aggregated!$L:$L)+SUMIF(CFwp_Aggregated!$B:$B,공시CF!A40,CFwp_Aggregated!$L:$L) -> 291105997 | F40: =SUM(D40:E40) -> 291105997 | K40: 선수금/Intercompany | N40: =L40-M40 -> 0
A41: =CFwp_Aggregated!B104 -> L1002 | C41: 미지급금 | D41: =SUMIF(CFwp_Aggregated!$B:$B,공시CF!B41,CFwp_Aggregated!$L:$L)+SUMIF(CFwp_Aggregated!$B:$B,공시CF!A41,CFwp_Aggregated!$L:$L) -> 1295562133 | E41: =L38 -> -140479840 | F41: =SUM(D41:E41) -> 1155082293 | K41: 단기차입금/Intercompany | N41: =L41-M41 -> 0
...

Sheet B.연결조정분개 요약표
D1: IFRS Consol ADJ Entry | G1: 0
F2: 1179726013 | G2: 1179726013
C3: CoA | D3: 차변계정 | E3: 대변계정 | F3: 차변금액 | G3: 대변금액 | H3: Description | I3: 계정 | J3: Entity | L3: 내역
B4: 1. 투자주식 상계
C5: 1) 지분법 하의 종속회사 자본금과 본사 종속회사 투자주식간의 상계 | L5: 1. 투자주식 상계
C6: BN USA | J6: BN USA | L6: 1. 투자주식 상계
C7: S1001 | D7: 보통주자본금 | F7: 5898630 | H7: 불입자본과 투자주식 상계 | I7: 보통주자본금 | J7: BN USA | L7: 1. 투자주식 상계
C8: S2001 | D8: 주식발행초과금 | F8: 1173827383 | H8: (2019년 중 지배력 획득일) | I8: 주식발행초과금 | J8: BN USA | L8: 1. 투자주식 상계
C9: A2106 | E9: 종속기업투자 | G9: 1179726013 | I9: 종속기업투자 | J9: BN USA | L9: 1. 투자주식 상계
C10: S2001 | D10: 주식발행초과금 | F10: 546100000 | H10: 불입자본과 투자주식 상계 | I10: 주식발행초과금
C11: A2106 | E11: 종속기업투자 | G11: 546100000 | H11: (2020추가취득) | I11: 종속기업투자
I13: 1179726013 | J13: 1179726013 | L13: 0
B16: 3. 내부거래 상계 | L16: 3. 내부거래 상계
C17: 1) 채권채무 상계 | J17: 1) 채권채무 상계 | L17: 3. 내부거래 상계
C18: L1001 | D18: 외상매입금 | F18: 140479840 | J18: 1) 채권채무 상계 | L18: 3. 내부거래 상계
C19: A1106 | E19: 외상매출금 | G19: 140479840 | J19: 1) 채권채무 상계 | L19: 3. 내부거래 상계
C21: 2) 수익비용 상계 | J21: 2) 수익비용 상계 | L21: 0
C22: P1101 | D22: 상품매출 | F22: 327302099 | J22: 2) 수익비용 상계 | L22: 0
C23: E1001 | E23: 상품매출원가 | G23: 327302099 | J23: 2) 수익비용 상계 | L23: 0
B25: 4. 재고자산 미실현손익 제거 | L25: 4. 재고자산 미실현손익 제거
L26: 4. 재고자산 미실현손익 제거
C27: P1101 | D27: 상품매출 | F27: 40638930 | L27: 4. 재고자산 미실현손익 제거
C28: A1201 | E28: 상품 | G28: 40638930 | L28: 4. 재고자산 미실현손익 제거
L29: 4. 재고자산 미실현손익 제거
L30: 4. 재고자산 미실현손익 제거
L31: 4. 재고자산 미실현손익 제거
B33: 5. 지분법 회계처리 | L33: 5. 지분법 회계처리
C34: 1) SDB korea 2019년 11월 7일 취득(2019년 9월말 취득 간주 3Q후 3개월 변동) 지분법 평가 | L34: 5. 지분법 회계처리
C35: =IFERROR(IFERROR(INDEX([196]CoA!$B:$B,MATCH('[196]B.연결조정분개 요약표'!D33,[196]CoA!C:C,0)),INDEX([196]CoA!$B:$B,MATCH('[196]B.연결조정분개 요약표'!E33,[196]CoA!C:C,0))),"") | L35: 5. 지분법 회계처리
C36: =IFERROR(IFERROR(INDEX([196]CoA!$B:$B,MATCH('[196]B.연결조정분개 요약표'!D34,[196]CoA!C:C,0)),INDEX([196]CoA!$B:$B,MATCH('[196]B.연결조정분개 요약표'!E34,[196]CoA!C:C,0))),"") | L36: 5. 지분법 회계처리
C37: A2107 | D37: 관계기업투자 | F37: -158512516 | L37: 5. 지분법 회계처리
C38: S4004 | E38: 미처분이익잉여금 | G38: -158512516 | L38: 5. 지분법 회계처리
L39: 5. 지분법 회계처리
L40: 5. 지분법 회계처리
C41: S4002 | D41: 관계기업의이익잉여금에대한지분(AOCI) | F41: 209382 | L41: 5. 지분법 회계처리
C42: S5001 | D42: 관계기업의기타포괄손익에대한지분(AOCI) | F42: 24667298 | L42: 5. 지분법 회계처리
C43: S5001 | D43: 관계기업의기타포괄손익에대한지분(AOCI) | F43: 8072230 | L43: 5. 지분법 회계처리
L44: 5. 지분법 회계처리
C45: A2107 | E45: 관계기업투자 | G45: 209382 | L45: 5. 지분법 회계처리
C46: A2107 | E46: 관계기업투자 | G46: 24667298 | L46: 5. 지분법 회계처리
...

Sheet CFwp_Aggregated
C1: ='A-1. 별도FS_20'!D1 -> 연결 v6.0
D2: CF Worksheet - Aggregated
C4: =[197]정산표!C5 -> Balance Verification | D4: =D100-D153 -> 0 | E4: =E100-E153 -> 544000000 | F4: 검증 | G4: =SUM(G8:G153) -> 0 | T4: 대차검증 | V4: =T154-V154 -> 0 | X4: =SUM(W10:W153)-SUM(X10:X153) -> 0 | Z4: =SUM(Y10:Y153)-SUM(Z10:Z153) -> -20300003
B5: Account Code | C5: Account | D5: 43830 | E5: 44196 | F5: 증감 | G5: 검증 | J5: 영업활동으로 인한 현금흐름 | O5: 투자활동 | Q5: 재무활동 | S5: 대체 | W5: Merger with | Y5: 외화환산
D6: K-IFRS | E6: K-IFRS | H6: Description | I6: Amount | J6: 유출없는비용 | K6: 유입없는수익 | L6: 간접법 | M6: 직접법 | N6: 자산증감 (현금유출입) | O6: 현금유입 | P6: 현금유출 | Q6: 현금유입 | R6: 현금유출 | S6: Description #No | T6: 차변금액 | U6: Description #No | V6: 대변금액 | W6: 차변금액 | X6: 대변금액 | Y6: 차변 | Z6: 대변
C7: 자산
C8: 유동자산 | D8: =D9+D34 -> 24638446052 | E8: =E9+E34 -> 574153013684
C9: 당좌자산 | D9: =SUM(D10:D33) -> 16881583202 | E9: =SUM(E10:E33) -> 521058894587
B10: A1101 | C10: 현금시재 | D10: =CFwp_Korea!D10+CFwp_US_KRW!D10 -> 1058619929 | E10: =CFwp_Korea!E10+CFwp_US_KRW!E10 -> 9847943 | H10: 외화환산이익 | I10: =CFwp_Korea!I10+CFwp_US_KRW!I10 -> 0 | J10: =CFwp_Korea!J10+CFwp_US_KRW!J10 -> 384991529 | K10: =CFwp_Korea!K10+CFwp_US_KRW!K10 -> 0 | L10: =CFwp_Korea!L10+CFwp_US_KRW!L10 -> 0 | M10: =CFwp_Korea!M10+CFwp_US_KRW!M10 -> 0 | N10: =CFwp_Korea!N10+CFwp_US_KRW!N10 -> 0 | O10: =CFwp_Korea!O10+CFwp_US_KRW!O10 -> 0 | P10: =CFwp_Korea!P10+CFwp_US_KRW!P10 -> 0 | ... Z10: =CFwp_Korea!Z10+CFwp_US_KRW!Z10 -> 0
B11: A1102 | C11: 보통예금 | D11: =CFwp_Korea!D11+CFwp_US_KRW!D11 -> 5517522912 | E11: =CFwp_Korea!E11+CFwp_US_KRW!E11 -> 123627275922 | H11: 외화환산손실 | I11: =CFwp_Korea!I11+CFwp_US_KRW!I11 -> 384991529 | J11: =CFwp_Korea!J11+CFwp_US_KRW!J11 -> 0 | K11: =CFwp_Korea!K11+CFwp_US_KRW!K11 -> 0 | L11: =CFwp_Korea!L11+CFwp_US_KRW!L11 -> 0 | M11: =CFwp_Korea!M11+CFwp_US_KRW!M11 -> 0 | N11: =CFwp_Korea!N11+CFwp_US_KRW!N11 -> 0 | O11: =CFwp_Korea!O11+CFwp_US_KRW!O11 -> 0 | P11: =CFwp_Korea!P11+CFwp_US_KRW!P11 -> 0 | ... Z11: =CFwp_Korea!Z11+CFwp_US_KRW!Z11 -> 0
B12: A1103 | C12: 국고보조금-현금및현금성자산 | D12: =CFwp_Korea!D12+CFwp_US_KRW!D12 -> 0 | E12: =CFwp_Korea!E12+CFwp_US_KRW!E12 -> -13293321 | I12: =CFwp_Korea!I12+CFwp_US_KRW!I12 -> 0 | J12: =CFwp_Korea!J12+CFwp_US_KRW!J12 -> 0 | K12: =CFwp_Korea!K12+CFwp_US_KRW!K12 -> 0 | L12: =CFwp_Korea!L12+CFwp_US_KRW!L12 -> 0 | M12: =CFwp_Korea!M12+CFwp_US_KRW!M12 -> 0 | N12: =CFwp_Korea!N12+CFwp_US_KRW!N12 -> 0 | O12: =CFwp_Korea!O12+CFwp_US_KRW!O12 -> 0 | P12: =CFwp_Korea!P12+CFwp_US_KRW!P12 -> 0 | ... Z12: =CFwp_Korea!Z12+CFwp_US_KRW!Z12 -> 0
B13: A1104 | C13: 정기예.적금 | D13: =CFwp_Korea!D13+CFwp_US_KRW!D13 -> 0 | E13: =CFwp_Korea!E13+CFwp_US_KRW!E13 -> 40000000000 | F13: =E13-D13 -> 40000000000 | G13: =J13-K13+N13+O13-P13+Q13-R13-T13+V13+F13-W13+X13-Y13+Z13 -> 0 | I13: =CFwp_Korea!I13+CFwp_US_KRW!I13 -> 0 | J13: =CFwp_Korea!J13+CFwp_US_KRW!J13 -> 0 | K13: =CFwp_Korea!K13+CFwp_US_KRW!K13 -> 0 | L13: =CFwp_Korea!L13+CFwp_US_KRW!L13 -> 0 | M13: =CFwp_Korea!M13+CFwp_US_KRW!M13 -> 0 | N13: =CFwp_Korea!N13+CFwp_US_KRW!N13 -> 0 | O13: =CFwp_Korea!O13+CFwp_US_KRW!O13 -> 0 | P13: =CFwp_Korea!P13+CFwp_US_KRW!P13 -> 40000000000 | ... Z13: =CFwp_Korea!Z13+CFwp_US_KRW!Z13 -> 0
B14: A1105 | C14: 당기손익-공정가치금융자산(유동) | D14: =CFwp_Korea!D14+CFwp_US_KRW!D14 -> 1001420524 | E14: =CFwp_Korea!E14+CFwp_US_KRW!E14 -> 40530571199 | F14: =E14-D14 -> 39529150675 | G14: =J14-K14+N14+O14-P14+Q14-R14-T14+V14+F14-W14+X14-Y14+Z14 -> 0 | H14: 금융자산평가이익 | I14: =CFwp_Korea!I14+CFwp_US_KRW!I14 -> 29150675 | J14: =CFwp_Korea!J14+CFwp_US_KRW!J14 -> 0 | K14: =CFwp_Korea!K14+CFwp_US_KRW!K14 -> 36575537 | L14: =CFwp_Korea!L14+CFwp_US_KRW!L14 -> 0 | M14: =CFwp_Korea!M14+CFwp_US_KRW!M14 -> 0 | N14: =CFwp_Korea!N14+CFwp_US_KRW!N14 -> 0 | O14: =CFwp_Korea!O14+CFwp_US_KRW!O14 -> 8107424862 | P14: =CFwp_Korea!P14+CFwp_US_KRW!P14 -> 47600000000 | ... Z14: =CFwp_Korea!Z14+CFwp_US_KRW!Z14 -> 0
H15: 금융자산처분이익 | I15: =CFwp_Korea!I15+CFwp_US_KRW!I15 -> 7424862 | J15: =CFwp_Korea!J15+CFwp_US_KRW!J15 -> 0 | K15: =CFwp_Korea!K15+CFwp_US_KRW!K15 -> 0 | L15: =CFwp_Korea!L15+CFwp_US_KRW!L15 -> 0 | M15: =CFwp_Korea!M15+CFwp_US_KRW!M15 -> 0 | N15: =CFwp_Korea!N15+CFwp_US_KRW!N15 -> 0 | O15: =CFwp_Korea!O15+CFwp_US_KRW!O15 -> 0 | P15: =CFwp_Korea!P15+CFwp_US_KRW!P15 -> 0 | ... Z15: =CFwp_Korea!Z15+CFwp_US_KRW!Z15 -> 0
B16: A1106 | C16: 외상매출금 | D16: =CFwp_Korea!D16+CFwp_US_KRW!D16 -> 9358066120 | E16: =CFwp_Korea!E16+CFwp_US_KRW!E16 -> 311336848615 | F16: =E16-D16 -> 301978782495 | G16: =J16-K16+N16+O16-P16+Q16-R16-T16+V16+F16-W16+X16-Y16+Z16 -> 0 | H16: 외화환산이익 | I16: =CFwp_Korea!I16+CFwp_US_KRW!I16 -> 0 | J16: =CFwp_Korea!J16+CFwp_US_KRW!J16 -> 3249273607 | K16: =CFwp_Korea!K16+CFwp_US_KRW!K16 -> 0 | L16: =CFwp_Korea!L16+CFwp_US_KRW!L16 -> -305620951415 | M16: =CFwp_Korea!M16+CFwp_US_KRW!M16 -> 0 | N16: =CFwp_Korea!N16+CFwp_US_KRW!N16 -> -305620951415 | O16: =CFwp_Korea!O16+CFwp_US_KRW!O16 -> 0 | P16: =CFwp_Korea!P16+CFwp_US_KRW!P16 -> 0 | ... Z16: =CFwp_Korea!Z16+CFwp_US_KRW!Z16 -> 8485086
D17: =CFwp_Korea!D17+CFwp_US_KRW!D17 -> 0 | E17: =CFwp_Korea!E17+CFwp_US_KRW!E17 -> 0 | G17: =J17-K17+N17+O17-P17+Q17-R17-T17+V17+F17-W17+X17-Y17+Z17 -> 0 | H17: 외화환산손실 | I17: =CFwp_Korea!I17+CFwp_US_KRW!I17 -> 3249273607 | J17: =CFwp_Korea!J17+CFwp_US_KRW!J17 -> 0 | K17: =CFwp_Korea!K17+CFwp_US_KRW!K17 -> 0 | L17: =CFwp_Korea!L17+CFwp_US_KRW!L17 -> 0 | M17: =CFwp_Korea!M17+CFwp_US_KRW!M17 -> 0 | N17: =CFwp_Korea!N17+CFwp_US_KRW!N17 -> 0 | O17: =CFwp_Korea!O17+CFwp_US_KRW!O17 -> 0 | P17: =CFwp_Korea!P17+CFwp_US_KRW!P17 -> 0 | ... Z17: =CFwp_Korea!Z17+CFwp_US_KRW!Z17 -> 0
B18: A1106C | C18: 외상매출금/Intercompany | D18: =CFwp_Korea!D18+CFwp_US_KRW!D18 -> 0 | E18: =CFwp_Korea!E18+CFwp_US_KRW!E18 -> 0 | F18: =E18-D18 -> 0 | G18: =J18-K18+N18+O18-P18+Q18-R18-T18+V18+F18-W18+X18-Y18+Z18 -> 0 | H18: 대손상각비 | I18: =CFwp_Korea!I18+CFwp_US_KRW!I18 -> 0 | J18: =CFwp_Korea!J18+CFwp_US_KRW!J18 -> 0 | K18: =CFwp_Korea!K18+CFwp_US_KRW!K18 -> 0 | L18: =CFwp_Korea!L18+CFwp_US_KRW!L18 -> 0 | M18: =CFwp_Korea!M18+CFwp_US_KRW!M18 -> 0 | N18: =CFwp_Korea!N18+CFwp_US_KRW!N18 -> 0 | O18: =CFwp_Korea!O18+CFwp_US_KRW!O18 -> 0 | P18: =CFwp_Korea!P18+CFwp_US_KRW!P18 -> 0 | ... Z18: =CFwp_Korea!Z18+CFwp_US_KRW!Z18 -> 0
B19: A1106-1 | C19: 현재가치할인차금(유동)-외상매출금 | D19: =CFwp_Korea!D19+CFwp_US_KRW!D19 -> 0 | E19: =CFwp_Korea!E19+CFwp_US_KRW!E19 -> 0 | F19: =E19-D19 -> 0 | G19: =J19-K19+N19+O19-P19+Q19-R19-T19+V19+F19-W19+X19-Y19+Z19 -> 0 | H19: 이자수익(금융) | I19: =CFwp_Korea!I19+CFwp_US_KRW!I19 -> 0 | J19: =CFwp_Korea!J19+CFwp_US_KRW!J19 -> 0 | K19: =CFwp_Korea!K19+CFwp_US_KRW!K19 -> 0 | L19: =CFwp_Korea!L19+CFwp_US_KRW!L19 -> 0 | M19: =CFwp_Korea!M19+CFwp_US_KRW!M19 -> 0 | N19: =CFwp_Korea!N19+CFwp_US_KRW!N19 -> 0 | O19: =CFwp_Korea!O19+CFwp_US_KRW!O19 -> 0 | P19: =CFwp_Korea!P19+CFwp_US_KRW!P19 -> 0 | ... Z19: =CFwp_Korea!Z19+CFwp_US_KRW!Z19 -> 0
B20: A1107 | C20: 대손충당금-외상매출금 | D20: =CFwp_Korea!D20+CFwp_US_KRW!D20 -> -533323483 | E20: =CFwp_Korea!E20+CFwp_US_KRW!E20 -> -619075951 | F20: =E20-D20 -> -85752468 | G20: =J20-K20+N20+O20-P20+Q20-R20-T20+V20+F20-W20+X20-Y20+Z20 -> 0 | H20: 대손상각비 | I20: =CFwp_Korea!I20+CFwp_US_KRW!I20 -> 470162695 | J20: =CFwp_Korea!J20+CFwp_US_KRW!J20 -> 470162695 | K20: =CFwp_Korea!K20+CFwp_US_KRW!K20 -> 0 | L20: =CFwp_Korea!L20+CFwp_US_KRW!L20 -> 0 | M20: =CFwp_Korea!M20+CFwp_US_KRW!M20 -> 0 | N20: =CFwp_Korea!N20+CFwp_US_KRW!N20 -> 0 | O20: =CFwp_Korea!O20+CFwp_US_KRW!O20 -> 0 | P20: =CFwp_Korea!P20+CFwp_US_KRW!P20 -> 0 | ... Z20: =CFwp_Korea!Z20+CFwp_US_KRW!Z20 -> 0
B21: A1107C | C21: 대손충당금-외상매출금/Intercompany | D21: =CFwp_Korea!D21+CFwp_US_KRW!D21 -> 0 | E21: =CFwp_Korea!E21+CFwp_US_KRW!E21 -> 0 | F21: =E21-D21 -> 0 | G21: =J21-K21+N21+O21-P21+Q21-R21-T21+V21+F21-W21+X21-Y21+Z21 -> 0 | I21: =CFwp_Korea!I21+CFwp_US_KRW!I21 -> 0 | J21: =CFwp_Korea!J21+CFwp_US_KRW!J21 -> 0 | K21: =CFwp_Korea!K21+CFwp_US_KRW!K21 -> 0 | L21: =CFwp_Korea!L21+CFwp_US_KRW!L21 -> 0 | M21: =CFwp_Korea!M21+CFwp_US_KRW!M21 -> 0 | N21: =CFwp_Korea!N21+CFwp_US_KRW!N21 -> 0 | O21: =CFwp_Korea!O21+CFwp_US_KRW!O21 -> 0 | P21: =CFwp_Korea!P21+CFwp_US_KRW!P21 -> 0 | ... Z21: =CFwp_Korea!Z21+CFwp_US_KRW!Z21 -> 0
B22: A1109 | C22: 단기대여금 | D22: =CFwp_Korea!D22+CFwp_US_KRW!D22 -> 0 | E22: =CFwp_Korea!E22+CFwp_US_KRW!E22 -> 0 | F22: =E22-D22 -> 0 | G22: =J22-K22+N22+O22-P22+Q22-R22-T22+V22+F22-W22+X22-Y22+Z22 -> 0 | I22: =CFwp_Korea!I22+CFwp_US_KRW!I22 -> 0 | J22: =CFwp_Korea!J22+CFwp_US_KRW!J22 -> 0 | K22: =CFwp_Korea!K22+CFwp_US_KRW!K22 -> 0 | L22: =CFwp_Korea!L22+CFwp_US_KRW!L22 -> 0 | M22: =CFwp_Korea!M22+CFwp_US_KRW!M22 -> 0 | N22: =CFwp_Korea!N22+CFwp_US_KRW!N22 -> 0 | O22: =CFwp_Korea!O22+CFwp_US_KRW!O22 -> 0 | P22: =CFwp_Korea!P22+CFwp_US_KRW!P22 -> 0 | ... Z22: =CFwp_Korea!Z22+CFwp_US_KRW!Z22 -> 0
B23: A1109-1 | C23: 현재가치할인차금-단기대여금 | D23: =CFwp_Korea!D23+CFwp_US_KRW!D23 -> 0 | E23: =CFwp_Korea!E23+CFwp_US_KRW!E23 -> 0 | F23: =E23-D23 -> 0 | G23: =J23-K23+N23+O23-P23+Q23-R23-T23+V23+F23-W23+X23-Y23+Z23 -> 0 | H23: 이자수익(금융) | I23: =CFwp_Korea!I23+CFwp_US_KRW!I23 -> 0 | J23: =CFwp_Korea!J23+CFwp_US_KRW!J23 -> 0 | K23: =CFwp_Korea!K23+CFwp_US_KRW!K23 -> 0 | L23: =CFwp_Korea!L23+CFwp_US_KRW!L23 -> 0 | M23: =CFwp_Korea!M23+CFwp_US_KRW!M23 -> 0 | N23: =CFwp_Korea!N23+CFwp_US_KRW!N23 -> 0 | O23: =CFwp_Korea!O23+CFwp_US_KRW!O23 -> 0 | P23: =CFwp_Korea!P23+CFwp_US_KRW!P23 -> 0 | ... Z23: =CFwp_Korea!Z23+CFwp_US_KRW!Z23 -> 0
B24: A1111 | C24: 미수수익 | D24: =CFwp_Korea!D24+CFwp_US_KRW!D24 -> 0 | E24: =CFwp_Korea!E24+CFwp_US_KRW!E24 -> 0 | F24: =E24-D24 -> 0 | G24: =J24-K24+N24+O24-P24+Q24-R24-T24+V24+F24-W24+X24-Y24+Z24 -> 0 | H24: 이자수익(금융) | I24: =CFwp_Korea!I24+CFwp_US_KRW!I24 -> 37557679 | J24: =CFwp_Korea!J24+CFwp_US_KRW!J24 -> 0 | K24: =CFwp_Korea!K24+CFwp_US_KRW!K24 -> 37557679 | L24: =CFwp_Korea!L24+CFwp_US_KRW!L24 -> 0 | M24: =CFwp_Korea!M24+CFwp_US_KRW!M24 -> 37557679 | N24: =CFwp_Korea!N24+CFwp_US_KRW!N24 -> 37557679 | O24: =CFwp_Korea!O24+CFwp_US_KRW!O24 -> 0 | P24: =CFwp_Korea!P24+CFwp_US_KRW!P24 -> 0 | ... Z24: =CFwp_Korea!Z24+CFwp_US_KRW!Z24 -> 0
B25: A1112 | C25: 미수금 | D25: =CFwp_Korea!D25+CFwp_US_KRW!D25 -> 145946788 | E25: =CFwp_Korea!E25+CFwp_US_KRW!E25 -> 86832198 | F25: =E25-D25 -> -59114590 | G25: =J25-K25+N25+O25-P25+Q25-R25-T25+V25+F25-W25+X25-Y25+Z25 -> 0 | H25: 외화환산손실 | I25: =CFwp_Korea!I25+CFwp_US_KRW!I25 -> 1635565 | J25: =CFwp_Korea!J25+CFwp_US_KRW!J25 -> 1635565 | K25: =CFwp_Korea!K25+CFwp_US_KRW!K25 -> 0 | L25: =CFwp_Korea!L25+CFwp_US_KRW!L25 -> 57479025 | M25: =CFwp_Korea!M25+CFwp_US_KRW!M25 -> 0 | N25: =CFwp_Korea!N25+CFwp_US_KRW!N25 -> 57479025 | O25: =CFwp_Korea!O25+CFwp_US_KRW!O25 -> 0 | P25: =CFwp_Korea!P25+CFwp_US_KRW!P25 -> 0 | ... Z25: =CFwp_Korea!Z25+CFwp_US_KRW!Z25 -> 0
B26: A1115 | C26: 선급금 | D26: =CFwp_Korea!D26+CFwp_US_KRW!D26 -> 306501376 | E26: =CFwp_Korea!E26+CFwp_US_KRW!E26 -> 6079778624 | F26: =E26-D26 -> 5773277248 | G26: =J26-K26+N26+O26-P26+Q26-R26-T26+V26+F26-W26+X26-Y26+Z26 -> 0 | H26: 법인세비용 | I26: =CFwp_Korea!I26+CFwp_US_KRW!I26 -> 460536740 | J26: =CFwp_Korea!J26+CFwp_US_KRW!J26 -> 460536740 | K26: =CFwp_Korea!K26+CFwp_US_KRW!K26 -> 0 | L26: =CFwp_Korea!L26+CFwp_US_KRW!L26 -> -6233813988 | M26: =CFwp_Korea!M26+CFwp_US_KRW!M26 -> 0 | N26: =CFwp_Korea!N26+CFwp_US_KRW!N26 -> -6233813988 | O26: =CFwp_Korea!O26+CFwp_US_KRW!O26 -> 0 | P26: =CFwp_Korea!P26+CFwp_US_KRW!P26 -> 0 | ... Z26: =CFwp_Korea!Z26+CFwp_US_KRW!Z26 -> 0
B27: A1116 | C27: 선급비용 | D27: =CFwp_Korea!D27+CFwp_US_KRW!D27 -> 26829036 | E27: =CFwp_Korea!E27+CFwp_US_KRW!E27 -> 20109358 | F27: =E27-D27 -> -6719678 | G27: =J27-K27+N27+O27-P27+Q27-R27-T27+V27+F27-W27+X27-Y27+Z27 -> 0 | I27: =CFwp_Korea!I27+CFwp_US_KRW!I27 -> 0 | J27: =CFwp_Korea!J27+CFwp_US_KRW!J27 -> 0 | K27: =CFwp_Korea!K27+CFwp_US_KRW!K27 -> 0 | L27: =CFwp_Korea!L27+CFwp_US_KRW!L27 -> 6719678 | M27: =CFwp_Korea!M27+CFwp_US_KRW!M27 -> 0 | N27: =CFwp_Korea!N27+CFwp_US_KRW!N27 -> 6719678 | O27: =CFwp_Korea!O27+CFwp_US_KRW!O27 -> 0 | P27: =CFwp_Korea!P27+CFwp_US_KRW!P27 -> 0 | ... Z27: =CFwp_Korea!Z27+CFwp_US_KRW!Z27 -> 0
B28: A1117 | C28: 부가세대급금 | D28: =CFwp_Korea!D28+CFwp_US_KRW!D28 -> 0 | E28: =CFwp_Korea!E28+CFwp_US_KRW!E28 -> 0 | F28: =E28-D28 -> 0 | G28: =J28-K28+N28+O28-P28+Q28-R28-T28+V28+F28-W28+X28-Y28+Z28 -> 0 | I28: =CFwp_Korea!I28+CFwp_US_KRW!I28 -> 0 | J28: =CFwp_Korea!J28+CFwp_US_KRW!J28 -> 0 | K28: =CFwp_Korea!K28+CFwp_US_KRW!K28 -> 0 | L28: =CFwp_Korea!L28+CFwp_US_KRW!L28 -> 0 | M28: =CFwp_Korea!M28+CFwp_US_KRW!M28 -> 0 | N28: =CFwp_Korea!N28+CFwp_US_KRW!N28 -> 0 | O28: =CFwp_Korea!O28+CFwp_US_KRW!O28 -> 0 | P28: =CFwp_Korea!P28+CFwp_US_KRW!P28 -> 0 | ... Z28: =CFwp_Korea!Z28+CFwp_US_KRW!Z28 -> 0
B29: A1119 | C29: 당기법인세자산 | D29: =CFwp_Korea!D29+CFwp_US_KRW!D29 -> 0 | E29: =CFwp_Korea!E29+CFwp_US_KRW!E29 -> 0 | F29: =E29-D29 -> 0 | G29: =J29-K29+N29+O29-P29+Q29-R29-T29+V29+F29-W29+X29-Y29+Z29 -> 0 | I29: =CFwp_Korea!I29+CFwp_US_KRW!I29 -> 0 | J29: =CFwp_Korea!J29+CFwp_US_KRW!J29 -> 0 | K29: =CFwp_Korea!K29+CFwp_US_KRW!K29 -> 0 | L29: =CFwp_Korea!L29+CFwp_US_KRW!L29 -> 0 | M29: =CFwp_Korea!M29+CFwp_US_KRW!M29 -> 0 | N29: =CFwp_Korea!N29+CFwp_US_KRW!N29 -> 0 | O29: =CFwp_Korea!O29+CFwp_US_KRW!O29 -> 0 | P29: =CFwp_Korea!P29+CFwp_US_KRW!P29 -> 0 | ... Z29: =CFwp_Korea!Z29+CFwp_US_KRW!Z29 -> 0
B30: A1118 | C30: 유동성이연법인세자산 | D30: =CFwp_Korea!D30+CFwp_US_KRW!D30 -> 0 | E30: =CFwp_Korea!E30+CFwp_US_KRW!E30 -> 0 | F30: =E30-D30 -> 0 | G30: =J30-K30+N30+O30-P30+Q30-R30-T30+V30+F30-W30+X30-Y30+Z30 -> 0 | I30: =CFwp_Korea!I30+CFwp_US_KRW!I30 -> 0 | J30: =CFwp_Korea!J30+CFwp_US_KRW!J30 -> 0 | K30: =CFwp_Korea!K30+CFwp_US_KRW!K30 -> 0 | L30: =CFwp_Korea!L30+CFwp_US_KRW!L30 -> 0 | M30: =CFwp_Korea!M30+CFwp_US_KRW!M30 -> 0 | N30: =CFwp_Korea!N30+CFwp_US_KRW!N30 -> 0 | O30: =CFwp_Korea!O30+CFwp_US_KRW!O30 -> 0 | P30: =CFwp_Korea!P30+CFwp_US_KRW!P30 -> 0 | ... Z30: =CFwp_Korea!Z30+CFwp_US_KRW!Z30 -> 0
B31: A1121 | C31: 반환재고회수권(계약자산) | D31: =CFwp_Korea!D31+CFwp_US_KRW!D31 -> 0 | E31: =CFwp_Korea!E31+CFwp_US_KRW!E31 -> 0 | F31: =E31-D31 -> 0 | G31: =J31-K31+N31+O31-P31+Q31-R31-T31+V31+F31-W31+X31-Y31+Z31 -> 0 | I31: =CFwp_Korea!I31+CFwp_US_KRW!I31 -> 0 | J31: =CFwp_Korea!J31+CFwp_US_KRW!J31 -> 0 | K31: =CFwp_Korea!K31+CFwp_US_KRW!K31 -> 0 | L31: =CFwp_Korea!L31+CFwp_US_KRW!L31 -> 0 | M31: =CFwp_Korea!M31+CFwp_US_KRW!M31 -> 0 | N31: =CFwp_Korea!N31+CFwp_US_KRW!N31 -> 0 | O31: =CFwp_Korea!O31+CFwp_US_KRW!O31 -> 0 | P31: =CFwp_Korea!P31+CFwp_US_KRW!P31 -> 0 | ... Z31: =CFwp_Korea!Z31+CFwp_US_KRW!Z31 -> 0
B32: A1122 | C32: 계약자산 | D32: =CFwp_Korea!D32+CFwp_US_KRW!D32 -> 0 | E32: =CFwp_Korea!E32+CFwp_US_KRW!E32 -> 0 | F32: =E32-D32 -> 0 | G32: =J32-K32+N32+O32-P32+Q32-R32-T32+V32+F32-W32+X32-Y32+Z32 -> 0 | I32: =CFwp_Korea!I32+CFwp_US_KRW!I32 -> 0 | J32: =CFwp_Korea!J32+CFwp_US_KRW!J32 -> 0 | K32: =CFwp_Korea!K32+CFwp_US_KRW!K32 -> 0 | L32: =CFwp_Korea!L32+CFwp_US_KRW!L32 -> 0 | M32: =CFwp_Korea!M32+CFwp_US_KRW!M32 -> 0 | N32: =CFwp_Korea!N32+CFwp_US_KRW!N32 -> 0 | O32: =CFwp_Korea!O32+CFwp_US_KRW!O32 -> 0 | P32: =CFwp_Korea!P32+CFwp_US_KRW!P32 -> 0 | ... Z32: =CFwp_Korea!Z32+CFwp_US_KRW!Z32 -> 0
F33: =E33-D33 -> 0 | G33: =J33-K33+N33+O33-P33+Q33-R33-T33+V33+F33-W33+X33-Y33+Z33 -> 0 | I33: =CFwp_Korea!I33+CFwp_US_KRW!I33 -> 0 | J33: =CFwp_Korea!J33+CFwp_US_KRW!J33 -> 0 | K33: =CFwp_Korea!K33+CFwp_US_KRW!K33 -> 0 | L33: =CFwp_Korea!L33+CFwp_US_KRW!L33 -> 0 | M33: =CFwp_Korea!M33+CFwp_US_KRW!M33 -> 0 | N33: =CFwp_Korea!N33+CFwp_US_KRW!N33 -> 0 | O33: =CFwp_Korea!O33+CFwp_US_KRW!O33 -> 0 | P33: =CFwp_Korea!P33+CFwp_US_KRW!P33 -> 0 | ... Z33: =CFwp_Korea!Z33+CFwp_US_KRW!Z33 -> 0
B34: A1200 | C34: 재고자산 | D34: =SUM(D35:D47) -> 7756862850 | E34: =SUM(E35:E47) -> 53094119097 | F34: =E34-D34 -> 45337256247 | G34: =J34-K34+N34+O34-P34+Q34-R34-T34+V34+F34-W34+X34-Y34+Z34 -> 0 | H34: 재고자산평가손실 | I34: =CFwp_Korea!I34+CFwp_US_KRW!I34 -> 2840492158 | J34: =CFwp_Korea!J34+CFwp_US_KRW!J34 -> 2840492158 | K34: =CFwp_Korea!K34+CFwp_US_KRW!K34 -> 0 | L34: =CFwp_Korea!L34+CFwp_US_KRW!L34 -> -48181888500 | M34: =CFwp_Korea!M34+CFwp_US_KRW!M34 -> 0 | N34: =CFwp_Korea!N34+CFwp_US_KRW!N34 -> -48181888500 | O34: =CFwp_Korea!O34+CFwp_US_KRW!O34 -> 0 | P34: =CFwp_Korea!P34+CFwp_US_KRW!P34 -> 0 | ... Z34: =CFwp_Korea!Z34+CFwp_US_KRW!Z34 -> 4140095
B35: A1201 | C35: 상품 | D35: =CFwp_Korea!D35+CFwp_US_KRW!D35 -> 545308589 | E35: =CFwp_Korea!E35+CFwp_US_KRW!E35 -> 1072162530 | I35: =CFwp_Korea!I35+CFwp_US_KRW!I35 -> 0 | J35: =CFwp_Korea!J35+CFwp_US_KRW!J35 -> 0 | K35: =CFwp_Korea!K35+CFwp_US_KRW!K35 -> 0 | L35: =CFwp_Korea!L35+CFwp_US_KRW!L35 -> 0 | M35: =CFwp_Korea!M35+CFwp_US_KRW!M35 -> 0 | N35: =CFwp_Korea!N35+CFwp_US_KRW!N35 -> 0 | O35: =CFwp_Korea!O35+CFwp_US_KRW!O35 -> 0 | P35: =CFwp_Korea!P35+CFwp_US_KRW!P35 -> 0 | ... Z35: =CFwp_Korea!Z35+CFwp_US_KRW!Z35 -> 0
B36: A1202 | C36: 제품 | D36: =CFwp_Korea!D36+CFwp_US_KRW!D36 -> 524830179 | E36: =CFwp_Korea!E36+CFwp_US_KRW!E36 -> 9749294700 | I36: =CFwp_Korea!I36+CFwp_US_KRW!I36 -> 0 | J36: =CFwp_Korea!J36+CFwp_US_KRW!J36 -> 0 | K36: =CFwp_Korea!K36+CFwp_US_KRW!K36 -> 0 | L36: =CFwp_Korea!L36+CFwp_US_KRW!L36 -> 0 | M36: =CFwp_Korea!M36+CFwp_US_KRW!M36 -> 0 | N36: =CFwp_Korea!N36+CFwp_US_KRW!N36 -> 0 | O36: =CFwp_Korea!O36+CFwp_US_KRW!O36 -> 0 | P36: =CFwp_Korea!P36+CFwp_US_KRW!P36 -> 0 | ... Z36: =CFwp_Korea!Z36+CFwp_US_KRW!Z36 -> 0
B37: A1203 | C37: 제품평가충당금 | D37: =CFwp_Korea!D37+CFwp_US_KRW!D37 -> 0 | E37: =CFwp_Korea!E37+CFwp_US_KRW!E37 -> -692503942 | I37: =CFwp_Korea!I37+CFwp_US_KRW!I37 -> 0 | J37: =CFwp_Korea!J37+CFwp_US_KRW!J37 -> 0 | K37: =CFwp_Korea!K37+CFwp_US_KRW!K37 -> 0 | L37: =CFwp_Korea!L37+CFwp_US_KRW!L37 -> 0 | M37: =CFwp_Korea!M37+CFwp_US_KRW!M37 -> 0 | N37: =CFwp_Korea!N37+CFwp_US_KRW!N37 -> 0 | O37: =CFwp_Korea!O37+CFwp_US_KRW!O37 -> 0 | P37: =CFwp_Korea!P37+CFwp_US_KRW!P37 -> 0 | ... Z37: =CFwp_Korea!Z37+CFwp_US_KRW!Z37 -> 0
B38: A1204 | C38: 원재료 | D38: =CFwp_Korea!D38+CFwp_US_KRW!D38 -> 3077150977 | E38: =CFwp_Korea!E38+CFwp_US_KRW!E38 -> 17942503420 | I38: =CFwp_Korea!I38+CFwp_US_KRW!I38 -> 0 | J38: =CFwp_Korea!J38+CFwp_US_KRW!J38 -> 0 | K38: =CFwp_Korea!K38+CFwp_US_KRW!K38 -> 0 | L38: =CFwp_Korea!L38+CFwp_US_KRW!L38 -> 0 | M38: =CFwp_Korea!M38+CFwp_US_KRW!M38 -> 0 | N38: =CFwp_Korea!N38+CFwp_US_KRW!N38 -> 0 | O38: =CFwp_Korea!O38+CFwp_US_KRW!O38 -> 0 | P38: =CFwp_Korea!P38+CFwp_US_KRW!P38 -> 0 | ... Z38: =CFwp_Korea!Z38+CFwp_US_KRW!Z38 -> 0
B39: A1205 | C39: 원재료평가충당금 | D39: =CFwp_Korea!D39+CFwp_US_KRW!D39 -> 0 | E39: =CFwp_Korea!E39+CFwp_US_KRW!E39 -> -840869466 | I39: =CFwp_Korea!I39+CFwp_US_KRW!I39 -> 0 | J39: =CFwp_Korea!J39+CFwp_US_KRW!J39 -> 0 | K39: =CFwp_Korea!K39+CFwp_US_KRW!K39 -> 0 | L39: =CFwp_Korea!L39+CFwp_US_KRW!L39 -> 0 | M39: =CFwp_Korea!M39+CFwp_US_KRW!M39 -> 0 | N39: =CFwp_Korea!N39+CFwp_US_KRW!N39 -> 0 | O39: =CFwp_Korea!O39+CFwp_US_KRW!O39 -> 0 | P39: =CFwp_Korea!P39+CFwp_US_KRW!P39 -> 0 | ... Z39: =CFwp_Korea!Z39+CFwp_US_KRW!Z39 -> 0
B40: A1206 | C40: 부재료 | D40: =CFwp_Korea!D40+CFwp_US_KRW!D40 -> 920887954 | E40: =CFwp_Korea!E40+CFwp_US_KRW!E40 -> 8982567553 | I40: =CFwp_Korea!I40+CFwp_US_KRW!I40 -> 0 | J40: =CFwp_Korea!J40+CFwp_US_KRW!J40 -> 0 | K40: =CFwp_Korea!K40+CFwp_US_KRW!K40 -> 0 | L40: =CFwp_Korea!L40+CFwp_US_KRW!L40 -> 0 | M40: =CFwp_Korea!M40+CFwp_US_KRW!M40 -> 0 | N40: =CFwp_Korea!N40+CFwp_US_KRW!N40 -> 0 | O40: =CFwp_Korea!O40+CFwp_US_KRW!O40 -> 0 | P40: =CFwp_Korea!P40+CFwp_US_KRW!P40 -> 0 | ... Z40: =CFwp_Korea!Z40+CFwp_US_KRW!Z40 -> 0
B41: A1207 | C41: 재공품 | D41: =CFwp_Korea!D41+CFwp_US_KRW!D41 -> 2682244471 | E41: =CFwp_Korea!E41+CFwp_US_KRW!E41 -> 17547814739 | I41: =CFwp_Korea!I41+CFwp_US_KRW!I41 -> 0 | J41: =CFwp_Korea!J41+CFwp_US_KRW!J41 -> 0 | K41: =CFwp_Korea!K41+CFwp_US_KRW!K41 -> 0 | L41: =CFwp_Korea!L41+CFwp_US_KRW!L41 -> 0 | M41: =CFwp_Korea!M41+CFwp_US_KRW!M41 -> 0 | N41: =CFwp_Korea!N41+CFwp_US_KRW!N41 -> 0 | O41: =CFwp_Korea!O41+CFwp_US_KRW!O41 -> 0 | P41: =CFwp_Korea!P41+CFwp_US_KRW!P41 -> 0 | ... Z41: =CFwp_Korea!Z41+CFwp_US_KRW!Z41 -> 0
...

Sheet CFwp_Korea
B1: 정산표 | C1: 별도 정산표 v6.0
D2: CF Worksheet
C4: =[197]정산표!C5 -> Balance Verification | D4: =D100-D153 -> 0 | E4: =E100-E153 -> 0 | F4: 검증 | G4: =SUM(G8:G153) -> 0 | T4: 대차검증 | V4: =T154-V154 -> 0 | X4: =SUM(W10:W153)-SUM(X10:X153) -> 0
B5: Account Code | C5: Account | D5: 43830 | E5: 44196 | F5: 증감 | G5: 검증 | J5: 영업활동으로 인한 현금흐름 | O5: 투자활동 | Q5: 재무활동 | S5: 대체 | W5: Merger with
D6: K-IFRS | E6: K-IFRS | H6: Description | I6: Amount | J6: 유출없는비용 | K6: 유입없는수익 | L6: 간접법 | M6: 직접법 | N6: 자산증감 (현금유출입) | O6: 현금유입 | P6: 현금유출 | Q6: 현금유입 | R6: 현금유출 | S6: Description #No | T6: 차변금액 | U6: Description #No | V6: 대변금액 | W6: 차변금액 | X6: 대변금액
C7: 자산 | AB7: 자산
C8: 유동자산 | D8: =D9+D34 -> 23588598166 | E8: =E9+E34 -> 572917913876 | AB8: 유동자산
C9: 당좌자산 | D9: =SUM(D10:D33) -> 15831735316 | E9: =SUM(E10:E33) -> 519871359963 | AB9: 당좌자산
B10: A1101 | C10: 현금시재 | D10: =SUMIF('A-1. 별도FS_19'!$B:$B,CFwp_Korea!B10,'A-1. 별도FS_19'!$D:$D) -> 8772043 | E10: =SUMIF('A-1. 별도FS_20'!$B:$B,CFwp_Korea!B10,'A-1. 별도FS_20'!$D:$D) -> 9195143 | H10: 외화환산이익 | I10: 0 | J10: 384991529 | K10: 0 | N10: 0 | O10: 0 | P10: 0 | Q10: 0 | R10: 0 | T10: 0 | V10: 0 | AA10: A1101 | AB10: 현금시재 | AC10: =AA10=B10 -> TRUE
B11: A1102 | C11: 보통예금 | D11: =SUMIF('A-1. 별도FS_19'!$B:$B,CFwp_Korea!B11,'A-1. 별도FS_19'!$D:$D) -> 5517522912 | E11: =SUMIF('A-1. 별도FS_20'!$B:$B,CFwp_Korea!B11,'A-1. 별도FS_20'!$D:$D) -> 122537878506 | H11: 외화환산손실 | I11: 384991529 | N11: 0 | O11: 0 | P11: 0 | Q11: 0 | R11: 0 | T11: 0 | V11: 0 | AA11: A1102 | AB11: 보통예금 | AC11: =AA11=B11 -> TRUE
B12: A1103 | C12: 국고보조금-현금및현금성자산 | D12: =SUMIF('A-1. 별도FS_19'!$B:$B,CFwp_Korea!B12,'A-1. 별도FS_19'!$D:$D) -> 0 | E12: =SUMIF('A-1. 별도FS_20'!$B:$B,CFwp_Korea!B12,'A-1. 별도FS_20'!$D:$D) -> -13293321 | K12: 0 | N12: 0 | O12: 0 | P12: 0 | Q12: 0 | R12: 0 | T12: 0 | V12: 0 | AA12: A1103 | AB12: 국고보조금-현금및현금성자산 | AC12: =AA12=B12 -> TRUE
B13: A1104 | C13: 정기예.적금 | D13: =SUMIF('A-1. 별도FS_19'!$B:$B,CFwp_Korea!B13,'A-1. 별도FS_19'!$D:$D) -> 0 | E13: =SUMIF('A-1. 별도FS_20'!$B:$B,CFwp_Korea!B13,'A-1. 별도FS_20'!$D:$D) -> 40000000000 | F13: =E13-D13 -> 40000000000 | G13: =J13-K13+N13+O13-P13+Q13-R13-T13+V13+F13-W13+X13-Y13+Z13 -> 0 | N13: 0 | O13: 0 | P13: 40000000000 | Q13: 0 | R13: 0 | T13: 0 | V13: 0 | AA13: A1104 | AB13: 정기예.적금 | AC13: =AA13=B13 -> TRUE
